Workbook
Name \0: #REF!
Name \a: #REF!
Name __MO1: #REF!
Name _MO1: #REF!
Name ACR: #REF!
Name AR: #REF!
Name AZU: #REF!
Name BAI: #REF!
Name BDI: 1.43344312465585
Name BLE: #REF!
Name BLQ: #REF!
Name CAL: #REF!
Name CATO: #REF!
Name CER: #REF!
Name CIM: #REF!
Name CIMB: #REF!
Name CIMC: #REF!
Name CINC: #REF!
Name CMA: #REF!
Name CMO: #REF!
Name DEZ: #REF!
Name DEZN: #REF!
Name DEZO: #REF!
Name DEZS: #REF!
Name DEZT: #REF!
Name DOIS: #REF!
Name DOZE: #REF!
Name EE: #REF!
Name EMA: #REF!
Name EMO: #REF!
Name ENC: #REF!
Name erd: #REF!
Name ESM: #REF!
Name FE: #REF!
Name FXD: #REF!
Name FXU: #REF!
Name LIQB: #REF!
Name LS: '[4]M.O.'!#REF!
Name luiuz: #REF!
Name luiz: #REF!
Name LX: #REF!
Name MACR: #REF!
Name MCOR: #REF!
Name MFI: #REF!
Name MO: #REF!
Name NOVE: #REF!
Name OF: #REF!
Name OITO: #REF!
Name ONZE: #REF!
Name PE: #REF!
Name PRE: #REF!
Name Print_Area_MI: #REF!
Name PVA: #REF!
Name QUAT: #REF!
Name QUIN: #REF!
Name RAZ: #REF!
Name RMA: #REF!
Name RMO: #REF!
Name SE: #REF!
Name SEIS: #REF!

Sheet FC Total (6 lotes)
AE1: Total | Previsão | EC1: FIM DAS VENDAS
A2: Ville de Provence | BP2: 24 meses pós obra | CN2: 48 meses pós obra | CZ2: 60 meses pós obra
C3: 1 | D3: 2 | E3: 3 | F3: 4 | G3: 5 | H3: 6 | I3: 7 | J3: 8 | K3: 9 | L3: 10 | M3: 11 | N3: 12 | O3: 13 | P3: 14 | Q3: 15 | R3: 16 | S3: 17 | T3: 18 | U3: 19 | V3: 20 | W3: 21 | X3: 22 | Y3: 23 | Z3: 24 | AA3: 25 | AB3: 26 | AC3: 27 | AG3: 28 | AH3: 29 | AI3: 30 | AJ3: 31 | AK3: 32 | AL3: 33 | AM3: 34 | AN3: 35 | AO3: 36 | AP3: 37 | AQ3: 38 | AR3: 39 | AS3: 40 | AT3: 41 | AU3: 42 | AV3: 43 | AW3: 44 | AX3: 45 | AY3: 46 | AZ3: 47 | BA3: 48 | BB3: 49 | BC3: 50 | BD3: 51 | BE3: 52 | BF3: 53 | BG3: 54 | BH3: 55 | BI3: 56 | BJ3: 57 | BK3: 58 | BL3: 59 | BM3: 60 | BN3: 61 | BO3: 62 | BP3: 63 | BQ3: 64 | BR3: 65 | BS3: 66 | BT3: 67 | BU3: 68 | BV3: 69 | BW3: 70 | BX3: 71 | BY3: 72 | BZ3: 73 | CA3: 74 | CB3: 75 | CC3: 76 | CD3: 77 | CE3: 78 | CF3: 79 | CG3: 80 | CH3: 81 | CI3: 82 | CJ3: 83 | CK3: 84 | CL3: 85 | CM3: 86 | CN3: 87 | CO3: 88 | CP3: 89 | CQ3: 90 | CR3: 91 | CS3: 92 | CT3: 93 | CU3: 94 | CV3: 95 | CW3: 96 | CX3: 97 | CY3: 98 | CZ3: 99 | DA3: 100 | DB3: 101 | DC3: 102 | DD3: 103 | DE3: 104 | DF3: 105 | DG3: 106 | DH3: 107 | DI3: 108 | DJ3: 109 | DK3: 110 | DL3: 111 | DM3: 112 | DN3: 113 | DO3: 114 | DP3: 115 | DQ3: 116 | DR3: 117 | DS3: 118 | DT3: 119 | DU3: 120 | DV3: 121 | DW3: 122 | DX3: 123 | DY3: 124 | DZ3: 125 | EA3: 126 | EB3: 127 | EC3: 128 | ED3: 129 | EE3: 130 | EF3: 131 | EG3: 132 | EH3: 133 | EI3: 134 | EJ3: 135 | EK3: 136 | EL3: 137 | EM3: 138 | EN3: 139 | EO3: 140 | EP3: 141 | EQ3: 142 | ER3: 143 | ES3: 144 | ET3: 145 | EU3: 146 | EV3: 147 | EW3: 148 | EX3: 149 | EY3: 150 | EZ3: 151 | FA3: 152 | FB3: 153 | FC3: 154 | FD3: 155 | FE3: 156 | FF3: 157 | FG3: 158 | FH3: 159 | FI3: 160 | FJ3: 161 | FK3: 162 | FL3: 163 | FM3: 164 | FN3: 165 | FO3: 166 | FP3: 167 | FQ3: 168 | FR3: 169 | FS3: 170 | FT3: 171 | FU3: 172 | FV3: 173 | FW3: 174 | FX3: 175 | FY3: 176 | FZ3: 177 | GA3: 178 | GB3: 179 | GC3: 180 | GD3: 181 | GE3: 182 | GF3: 183 | GG3: 184 | GH3: 185 | GI3: 186 | GJ3: 187 | GK3: 188 | GL3: 189 | GM3: 190 | GN3: 191 | GO3: 192 | GP3: 193 | GQ3: 194 | GR3: 195 | GS3: 196 | GT3: 197 | GU3: 198 | GV3: 199 | GW3: 200 | GX3: 201 | GY3: 202 | GZ3: 203 | HA3: 204 | HB3: 205 | HC3: 206 | HD3: 207 | HE3: 208 | HF3: 209 | HG3: 210 | HH3: 211 | HI3: 212 | HJ3: 213 | HK3: 214 | HL3: 215 | HM3: 216 | HN3: 217 | HO3: 218 | HP3: 219 | HQ3: 220 | HR3: 221 | HS3: 222 | HT3: 223 | HU3: 224
A4: Fluxo de Caixa | B4: REALIZADO | M4: REALIZADO
C5: 44958 | D5: 44986 | E5: 45017 | F5: 45047 | G5: 45078 | H5: 45108 | I5: 45139 | J5: 45170 | K5: 45200 | L5: 45231 | M5: 45261 | N5: 45292 | O5: 45323 | P5: 45352 | Q5: 45383 | R5: 45413 | S5: 45444 | T5: 45474 | U5: 45505 | V5: 45536 | W5: 45566 | X5: 45597 | Y5: 45627 | Z5: 45658 | AA5: 45689 | AB5: 45717 | AC5: 45748 | AE5: Total | Previsão | AG5: 45778 | AH5: 45809 | AI5: 45839 | AJ5: 45870 | AK5: 45901 | AL5: 45931 | AM5: 45962 | AN5: 45992 | AO5: 46023 | AP5: 46054 | AQ5: 46082 | AR5: 46113 | AS5: 46143 | AT5: 46174 | AU5: 46204 | AV5: 46235 | AW5: 46266 | AX5: 46296 | AY5: 46327 | AZ5: 46357 | BA5: 46388 | BB5: 46419 | BC5: 46447 | BD5: 46478 | BE5: 46508 | BF5: 46539 | BG5: 46569 | BH5: 46600 | BI5: 46631 | BJ5: 46661 | BK5: 46692 | BL5: 46722 | BM5: 46753 | BN5: 46784 | BO5: 46813 | BP5: 46844 | BQ5: 46874 | BR5: 46905 | BS5: 46935 | BT5: 46966 | BU5: 46997 | BV5: 47027 | BW5: 47058 | BX5: 47088 | BY5: 47119 | BZ5: 47150 | CA5: 47178 | CB5: 47209 | CC5: 47239 | CD5: 47270 | CE5: 47300 | CF5: 47331 | CG5: 47362 | CH5: 47392 | CI5: 47423 | CJ5: 47453 | CK5: 47484 | CL5: 47515 | CM5: 47543 | CN5: 47574 | CO5: 47604 | CP5: 47635 | CQ5: 47665 | CR5: 47696 | CS5: 47727 | CT5: 47757 | CU5: 47788 | CV5: 47818 | CW5: 47849 | CX5: 47880 | CY5: 47908 | CZ5: 47939 | DA5: 47969 | DB5: 48000 | DC5: 48030 | DD5: 48061 | DE5: 48092 | DF5: 48122 | DG5: 48153 | DH5: 48183 | DI5: 48214 | DJ5: 48245 | DK5: 48274 | DL5: 48305 | DM5: 48335 | DN5: 48366 | DO5: 48396 | DP5: 48427 | DQ5: 48458 | DR5: 48488 | DS5: 48519 | DT5: 48549 | DU5: 48580 | DV5: 48611 | DW5: 48639 | DX5: 48670 | DY5: 48700 | DZ5: 48731 | EA5: 48761 | EB5: 48792 | EC5: 48823 | ED5: 48853 | EE5: 48884 | EF5: 48914 | EG5: 48945 | EH5: 48976 | EI5: 49004 | EJ5: 49035 | EK5: 49065 | EL5: 49096 | EM5: 49126 | EN5: 49157 | EO5: 49188 | EP5: 49218 | EQ5: 49249 | ER5: 49279 | ES5: 49310 | ET5: 49341 | EU5: 49369 | EV5: 49400 | EW5: 49430 | EX5: 49461 | EY5: 49491 | EZ5: 49522 | FA5: 49553 | FB5: 49583 | FC5: 49614 | FD5: 49644 | FE5: 49675 | FF5: 49706 | FG5: 49735 | FH5: 49766 | FI5: 49796 | FJ5: 49827 | FK5: 49857 | FL5: 49888 | FM5: 49919 | FN5: 49949 | FO5: 49980 | FP5: 50010 | FQ5: 50041 | FR5: 50072 | FS5: 50100 | FT5: 50131 | FU5: 50161 | FV5: 50192 | FW5: 50222 | FX5: 50253 | FY5: 50284 | FZ5: 50314 | GA5: 50345 | GB5: 50375 | GC5: 50406 | GD5: 50437 | GE5: 50465 | GF5: 50496 | GG5: 50526 | GH5: 50557 | GI5: 50587 | GJ5: 50618 | GK5: 50649 | GL5: 50679 | GM5: 50710 | GN5: 50740 | GO5: 50771 | GP5: 50802 | GQ5: 50830 | GR5: 50861 | GS5: 50891 | GT5: 50922 | GU5: 50952 | GV5: 50983 | GW5: 51014 | GX5: 51044 | GY5: 51075 | GZ5: 51105 | HA5: 51136 | HB5: 51167 | HC5: 51196 | HD5: 51227 | HE5: 51257 | HF5: 51288 | HG5: 51318 | HH5: 51349 | HI5: 51380 | HJ5: 51410 | HK5: 51441 | HL5: 51471 | HM5: 51502 | HN5: 51533 | HO5: 51561 | HP5: 51592 | HQ5: 51622 | HR5: 51653 | HS5: 51683 | HT5: 51714 | HU5: 51745
A7: RECEITAS
A8: ITBI | B8: =SUM(C8:Z8) | AB8: 338614.68 | AC8: 391548.5 | AE8: =SUM(AG8:FN8)
A9: Receitas Contratadas | B9: =SUM(C9:AB9) | AB9: 2857997.7 | AC9: 3156158.3 | AE9: =SUM(AG9:HU9) | AG9: 1198605.4 | AH9: 1028029.6 | AI9: 1028028.6 | AJ9: 1241129.9 | AK9: 1090966.8 | AL9: 1028028.6 | AM9: 1028028.6 | AN9: 1121274.7 | AO9: 994547.37 | AP9: 994547.39 | AQ9: 6631742.8 | AR9: 3022467.8 | AS9: 618470.15 | AT9: 618470.02 | AU9: 1033077.1 | AV9: 618470.02 | AW9: 618470.02 | AX9: 732035 | AY9: 618470.02 | AZ9: 677753.1 | BA9: 619601.51 | BB9: 619601.53 | BC9: 644682.56 | BD9: 1365576.9 | BE9: 289576.23 | BF9: 197087.28 | BG9: 197087.28 | BH9: 197087.28 | BI9: 197087.28 | BJ9: 197087.28 | BK9: 197087.28 | BL9: 255238.85 | BM9: 197960.48 | BN9: 197960.48 | BO9: 223012.69 | BP9: 734638.11 | BQ9: 129621.61 | BR9: 112417.25 | BS9: 112417.25 | BT9: 112417.25 | BU9: 112417.25 | BV9: 112417.25 | BW9: 112417.25 | BX9: 112417.25 | BY9: 112417.25 | BZ9: 112417.25 | CA9: 137477.17 | CB9: 378997.8 | CC9: 100986.26 | CD9: 100986.33 | CE9: 100986.33 | CF9: 100986.33 | CG9: 100986.33 | CH9: 100986.33 | CI9: 100986.33 | CJ9: 100986.33 | CK9: 100986.33 | CL9: 100986.33 | CM9: 126208.8 | CN9: 394315.24 | CO9: 90222.75 | CP9: 90222.81 | CQ9: 90222.81 | CR9: 90222.81 | CS9: 90222.81 | CT9: 90222.81 | CU9: 90222.81 | CV9: 90222.81 | CW9: 90222.81 | CX9: 90222.81 | CY9: 115388.14 | CZ9: 412983.94 | DA9: 70627.87 | DB9: 70627.86 | DC9: 70627.86 | DD9: 70627.86 | DE9: 70627.86 | DF9: 70627.86 | DG9: 70627.86 | DH9: 70627.86 | DI9: 70627.86 | DJ9: 70627.86 | DK9: 95765.25 | DL9: 425774.43 | DM9: 71382.89 | DN9: 71382.92 | DO9: 71382.92 | DP9: 71382.92 | DQ9: 71382.92 | DR9: 71382.92 | DS9: 71382.92 | DT9: 71382.92 | DU9: 71382.92 | DV9: 71382.92 | DW9: 96449.45 | DX9: 324486.21
A11: PREVISÃO DE RECEITAS(ESTOQUE)
A12: Vendas 06 Lotes a.m. | B12: =SUM(C12:W12) | D12: 0 | E12: 0 | F12: 0 | G12: 0 | H12: 0 | I12: 0 | J12: 0 | K12: 0 | L12: 0 | M12: 0 | N12: 0 | O12: 0 | P12: 0 | Q12: 0 | R12: 0 | S12: 0 | T12: 0 | U12: 0 | V12: 0 | AE12: =SUM(AG12:HU12) | AG12: 550415.8 | AH12: 662771.15 | AI12: 775126.49 | AJ12: 887481.83 | AK12: 999837.17 | AL12: 1112192.5 | AM12: 1224547.9 | AN12: 1336903.2 | AO12: 1449258.5 | AP12: 1561613.9 | AQ12: 1673969.2 | AR12: 1786324.6 | AS12: 2363217.6 | AT12: 2446015.3 | AU12: 2528813 | AV12: 2611610.8 | AW12: 2694408.5 | AX12: 2777206.2 | AY12: 2860004 | AZ12: 2942801.7 | BA12: 3025599.4 | BB12: 3108397.2 | BC12: 3207723.9 | BD12: 3293895.7 | BE12: 3380067.4 | BF12: 3406377.9 | BG12: 3432688.4 | BH12: 3458998.9 | BI12: 3485309.4 | BJ12: 3511619.9 | BK12: 3554459.4 | BL12: 3584143.9 | BM12: 3613828.4 | BN12: 3643513 | BO12: 3687147.6 | BP12: 3715944.5 | BQ12: 3744741.4 | BR12: 3773538.3 | BS12: 3802335.2 | BT12: 3847661.1 | BU12: 3879832.1 | BV12: 3912003 | BW12: 3958124.1 | BX12: 3989407.4 | BY12: 4020690.7 | BZ12: 4051974 | CA12: 4083257.4 | CB12: 4129272.1 | CC12: 4162131.8 | CD12: 4177672.6 | CE12: 4193213.4 | CF12: 4222704.3 | CG12: 4237357.5 | CH12: 4252010.7 | CI12: 4266663.9 | CJ12: 4296048.5 | CK12: 4312278.1 | CL12: 4328507.7 | CM12: 4344737.3 | CN12: 4374917 | CO12: 4390258.9 | CP12: 4405600.9 | CQ12: 4420942.9 | CR12: 4452813.9 | CS12: 4469732.3 | CT12: 4486650.6 | CU12: 4503569 | CV12: 4534437.5 | CW12: 4550468.2 | CX12: 4566499 | CY12: 4582529.8 | CZ12: 4598040.4 | DA12: 4628282.5 | DB12: 4645369.6 | DC12: 4662456.6 | DD12: 4693493.8 | DE12: 4709693.3 | DF12: 4725892.7 | DG12: 4742092.2 | DH12: 4757771.5 | DI12: 4788182.3 | DJ12: 4805438 | DK12: 4822693.8 | DL12: 4839949.6 | DM12: 4529831.5 | DN12: 4135202 | DO12: 4012222.5 | DP12: 3889243 | DQ12: 3763945.8 | DR12: 3638648.7 | DS12: 3513351.5 | DT12: 3388054.3 | DU12: 3276707.2 | DV12: 3150522.4 | DW12: 3024337.6 | DX12: 2898152.8 | DY12: 2483378.7 | DZ12: 2079518.8 | EA12: 1982057.2 | EB12: 1884595.7 | EC12: 1787134.2 | ED12: 1689672.6 | EE12: 1592211.1 | EF12: 1494749.6 | EG12: 1396768 | EH12: 1296988.7 | EI12: 1197209.5 | EJ12: 1097430.2 | EK12: 997650.95 | EL12: 934992.87 | EM12: 909455.97 | EN12: 883919.08 | EO12: 857862.09 | EP12: 831805.11 | EQ12: 805748.13 | ER12: 779691.14 | ES12: 753634.16 | ET12: 727577.17 | EU12: 701520.19 | EV12: 675294.51 | EW12: 649068.83 | EX12: 622323.07 | EY12: 595577.3 | EZ12: 568831.53 | FA12: 542085.77 | FB12: 515340 | FC12: 488594.23 | FD12: 461679.77 | FE12: 434765.31 | FF12: 407330.76 | FG12: 379896.21 | FH12: 352461.67 | FI12: 325027.12 | FJ12: 308332.37 | FK12: 302377.44 | FL12: 296422.5 | FM12: 290298.87 | FN12: 284175.24 | FO12: 278051.61 | FP12: 271927.98 | FQ12: 265804.35 | FR12: 259680.72 | FS12: 253557.09 | FT12: 247433.46 | FU12: 241141.14 | FV12: 234848.81 | FW12: 228556.49 | FX12: 222264.16 | FY12: 215971.84 | FZ12: 209679.51 | GA12: 203387.18 | GB12: 197094.86 | GC12: 190633.84 | GD12: 184172.82 | GE12: 177711.8 | GF12: 171250.78 | GG12: 164789.76 | GH12: 158328.74 | GI12: 151867.72 | GJ12: 145406.7 | GK12: 138776.98 | GL12: 132147.27 | GM12: 125517.55 | GN12: 118887.84 | GO12: 112258.12 | GP12: 105628.4 | GQ12: 98998.689 | GR12: 92368.974 | GS12: 85739.258 | GT12: 78940.848 | GU12: 72142.437 | GV12: 65344.027 | GW12: 58545.616 | GX12: 51747.206 | GY12: 44948.796 | GZ12: 38150.385 | HA12: 31351.975 | HB12: 24384.869 | HC12: 17417.764 | HD12: 10450.658 | HE12: 3483.5527 | HF12: 91207.789 | HG12: 85683.027 | HH12: 80017.684 | HI12: 74352.342 | HJ12: 68687 | HK12: 63021.658 | HL12: 57356.316 | HM12: 51690.974 | HN12: 46025.632 | HO12: 40360.29 | HP12: 34694.948 | HQ12: 29029.606 | HR12: 23223.685 | HS12: 17417.764 | HT12: 11611.842 | HU12: 5805.9212
A14: APORTE DE SÓCIOS
A15: Aportes | B15: =SUM(C15:Z15) | C15: 2004788.2 | Y15: 1000000 | Z15: 1000000 | AB15: 1000000 | AE15: =SUM(AG15:HU15) | AG15: 0 | AH15: 0 | AI15: 0 | AJ15: 0 | AK15: 0 | AL15: 0 | AM15: 0 | AN15: 0 | AO15: 0 | AP15: 0 | AQ15: 0 | AR15: 0 | AS15: 0 | AT15: 0 | AU15: 0 | AV15: 0 | AW15: 0 | AX15: 0 | AY15: 0 | AZ15: 0 | BA15: 0 | BB15: 0 | BD15: 0 | BE15: 0 | BF15: 0 | BG15: 0 | BH15: 0 | BI15: 0 | BJ15: 0 | BK15: 0 | BL15: 0 | BM15: 0 | BN15: 0 | BO15: 0 | BP15: 0 | BQ15: 0 | BR15: 0 | BS15: 0 | BT15: 0 | BU15: 0 | BV15: 0 | BW15: 0 | BX15: 0 | BY15: 0 | BZ15: 0 | CA15: 0 | CB15: 0 | CC15: 0 | CD15: 0 | CE15: 0 | CF15: 0 | CG15: 0 | CH15: 0 | CI15: 0 | CJ15: 0 | CK15: 0 | CL15: 0 | CM15: 0 | CN15: 0 | CO15: 0 | CP15: 0 | CQ15: 0 | CR15: 0 | CS15: 0 | CT15: 0 | CU15: 0 | CV15: 0 | CW15: 0 | CX15: 0 | CY15: 0 | CZ15: 0 | DA15: 0 | DB15: 0 | DC15: 0 | DD15: 0 | DE15: 0 | DF15: 0 | DG15: 0 | DH15: 0 | DI15: 0 | DJ15: 0 | DK15: 0 | DL15: 0 | DM15: 0 | DN15: 0 | DO15: 0 | DP15: 0 | DQ15: 0 | DR15: 0 | DS15: 0 | DT15: 0 | DU15: 0 | DV15: 0 | DW15: 0 | DX15: 0 | DY15: 0 | DZ15: 0 | EA15: 0 | EB15: 0 | EC15: 0 | ED15: 0 | EE15: 0 | EF15: 0 | EG15: 0 | EH15: 0 | EI15: 0 | EJ15: 0 | EK15: 0 | EL15: 0 | EM15: 0 | EN15: 0 | EO15: 0 | EP15: 0 | EQ15: 0 | ER15: 0 | ES15: 0 | ET15: 0 | EU15: 0 | EV15: 0 | EW15: 0 | EX15: 0 | EY15: 0 | EZ15: 0 | FA15: 0 | FB15: 0 | FC15: 0 | FD15: 0 | FE15: 0 | FF15: 0 | FG15: 0 | FH15: 0 | FI15: 0 | FJ15: 0 | FK15: 0 | FL15: 0 | FM15: 0 | FN15: 0 | FO15: 0 | FP15: 0 | FQ15: 0 | FR15: 0 | FS15: 0 | FT15: 0 | FU15: 0 | FV15: 0 | FW15: 0 | FX15: 0 | FY15: 0 | FZ15: 0 | GA15: 0 | GB15: 0 | GC15: 0 | GD15: 0 | GE15: 0 | GF15: 0 | GG15: 0 | GH15: 0 | GI15: 0 | GJ15: 0 | GK15: 0 | GL15: 0 | GM15: 0 | GN15: 0 | GO15: 0 | GP15: 0 | GQ15: 0 | GR15: 0 | GS15: 0 | GT15: 0 | GU15: 0 | GV15: 0 | GW15: 0 | GX15: 0 | GY15: 0 | GZ15: 0 | HA15: 0 | HB15: 0 | HC15: 0 | HD15: 0 | HE15: 0 | HF15: 0 | HG15: 0 | HH15: 0 | HI15: 0 | HJ15: 0 | HK15: 0 | HL15: 0 | HM15: 0 | HN15: 0 | HO15: 0 | HP15: 0 | HQ15: 0 | HR15: 0 | HS15: 0 | HT15: 0 | HU15: 0
A17: RECEITA FINANCEIRA (+)
A18: Rendimento Financeiro | B18: =SUM(C18:Z18) | AB18: 12646.02 | AC18: 38113.26 | AE18: =SUM(AG18:HU18) | AG18: =IF(AC74>0, AC74*0.5%,0) | AH18: =IF(AG74>0, AG74*0.5%,0) | AI18: =IF(AH74>0, AH74*0.5%,0) | AJ18: =IF(AI74>0, AI74*0.5%,0) | AK18: =IF(AJ74>0, AJ74*0.5%,0) | AL18: =IF(AK74>0, AK74*0.5%,0) | AM18: =IF(AL74>0, AL74*0.5%,0) | AN18: =IF(AM74>0, AM74*0.5%,0) | AO18: =IF(AN74>0, AN74*0.5%,0) | ... HU18: =IF(HT74>0, HT74*0.5%,0)
A20: TOTAL RECEITAS REAL (+) | B20: =SUM(C20:W20) | C20: =SUM(C8+C9+C15+C18) | D20: =SUM(D8+D9+D15+D18) | E20: =SUM(E8+E9+E15+E18) | F20: =SUM(F8+F9+F12+F15+F18) | G20: =SUM(G8+G9+G12+G15+G18) | H20: =SUM(H8+H9+H12+H15+H18) | I20: =SUM(I8+I9+I12+I15+I18) | J20: =SUM(J8+J9+J15+J18) | K20: =SUM(K8+K9+K15+K18) | L20: =SUM(L8+L9+L15+L18) | M20: =SUM(M8+M9+M15+M18) | N20: =SUM(N8+N9+N15+N18) | O20: =SUM(O8+O9+O15+O18) | P20: =SUM(P8+P9+P15+P18) | Q20: =SUM(Q8+Q9+Q15+Q18) | ... AC20: =SUM(AC8+AC9+AC15+AC18) | AE20: =SUM(AG20:DN20) | AG20: =SUM(AG8+AG9+AG15+AG18) | AH20: =SUM(AH8+AH9+AH15+AH18) | AI20: =SUM(AI8+AI9+AI15+AI18) | AJ20: =SUM(AJ8+AJ9+AJ15+AJ18) | AK20: =SUM(AK8+AK9+AK15+AK18) | AL20: =SUM(AL8+AL9+AL15+AL18) | AM20: =SUM(AM8+AM9+AM15+AM18) | AN20: =SUM(AN8+AN9+AN15+AN18) | ... HU20: =SUM(HU8+HU9+HU15+HU18)
A21: TOTAL DE RECEITAS + PREVISÃO VENDAS | B21: =SUM(C21:W21) | C21: =C12+C20 | D21: =D12+D20 | E21: =E12+E20 | F21: =F12+F20 | G21: =G12+G20 | H21: =H12+H20 | I21: =I12+I20 | J21: =J12+J9+J18+J15+J8 | K21: =K12+K9+K18+K15+K8 | L21: =L12+L9+L18+L15+L8 | M21: =M12+M9+M18+M15+M8 | N21: =N12+N9+N18+N15+N8 | O21: =O12+O9+O18+O15+O8 | P21: =P12+P9+P18+P15+P8 | Q21: =Q12+Q9+Q18+Q15+Q8 | ... AC21: =AC12+AC9+AC18+AC15+AC8 | AE21: =SUM(AG21:DN21) | AG21: =AG12+AG9+AG18+AG15+AG8 | AH21: =AH12+AH9+AH18+AH15+AH8 | AI21: =AI12+AI9+AI18+AI15+AI8 | AJ21: =AJ12+AJ9+AJ18+AJ15+AJ8 | AK21: =AK12+AK9+AK18+AK15+AK8 | AL21: =AL12+AL9+AL18+AL15+AL8 | AM21: =AM12+AM9+AM18+AM15+AM8 | AN21: =AN12+AN9+AN18+AN15+AN8 | ... HU21: =HU12+HU9+HU18+HU15+HU8
A23: DESPESAS OPERACIONAIS
A24: DESPESAS COMERCIAIS(-)
A25: Comissões S/ Venda (Equipe Interna) | B25: =SUM(C25:AA25) | AC25: -128438.23 | AE25: =SUM(AG25:HU25) | AG25: -28685.08 | AH25: -28685.08 | AI25: -28685.08 | AJ25: -28685.08 | AK25: -28685.08 | AL25: -28685.08 | AM25: -28685.08 | AN25: -28685.08 | AO25: -28685.08 | AP25: -28685.08 | AQ25: -28685.08 | AR25: -28685.08 | AS25: -28685.08 | AT25: -28685.08 | AU25: -28685.08 | AV25: -28685.08 | AW25: -28685.08 | AX25: -28685.08 | AY25: -28685.08 | AZ25: -28685.08 | BA25: -28685.08 | BB25: -28685.08 | BC25: -28685.08 | BD25: -28685.08 | BE25: -28685.08 | BF25: -28685.08 | BG25: -28685.08 | BH25: -28685.08 | BI25: -28685.08 | BJ25: -28685.08 | BK25: -28685.08 | BL25: -28685.08 | BM25: -28685.08 | BN25: -28685.08 | BO25: -28685.08 | BP25: -28685.08 | BQ25: -28685.08 | BR25: -28685.08 | BS25: -28685.08 | BT25: -28685.08 | BU25: -28685.08 | BV25: -28685.08 | BW25: -28685.08 | BX25: -28685.08 | BY25: -28685.08 | BZ25: -28685.08 | CA25: -28685.08 | CB25: -28685.08 | CC25: -28685.08 | CD25: -28685.08 | CE25: -28685.08 | CF25: -28685.08 | CG25: -28685.08 | CH25: -28685.08 | CI25: -28685.08 | CJ25: -28685.08 | CK25: -28685.08 | CL25: -28685.08 | CM25: -28685.08 | CN25: -28685.08 | CO25: -28685.08 | CP25: -28685.08 | DL25: 0 | DM25: 0 | DN25: 0 | DO25: 0 | DP25: 0 | DQ25: 0 | DR25: 0 | DS25: 0 | DT25: 0 | DU25: 0 | DV25: 0 | DW25: 0 | DX25: 0 | DY25: 0 | DZ25: 0 | EA25: 0 | EB25: 0 | EC25: 0 | ED25: 0 | EE25: 0 | EF25: 0 | EG25: 0 | EH25: 0 | EI25: 0 | EJ25: 0 | EK25: 0 | EL25: 0 | EM25: 0 | EN25: 0 | EO25: 0 | EP25: 0 | EQ25: 0 | ER25: 0 | ES25: 0 | ET25: 0 | EU25: 0 | EV25: 0 | EW25: 0 | EX25: 0 | EY25: 0 | EZ25: 0 | FA25: 0 | FB25: 0 | FC25: 0 | FD25: 0 | FE25: 0 | FF25: 0 | FG25: 0 | FH25: 0 | FI25: 0 | FJ25: 0 | FK25: 0 | FL25: 0 | FM25: 0 | FN25: 0 | FO25: 0 | FP25: 0 | FQ25: 0 | FR25: 0 | FS25: 0 | FT25: 0 | FU25: 0 | FV25: 0 | FW25: 0 | FX25: 0 | FY25: 0 | FZ25: 0 | GA25: 0 | GB25: 0 | GC25: 0 | GD25: 0 | GE25: 0 | GF25: 0 | GG25: 0 | GH25: 0 | GI25: 0 | GJ25: 0 | GK25: 0 | GL25: 0 | GM25: 0 | GN25: 0 | GO25: 0 | GP25: 0 | GQ25: 0 | GR25: 0 | GS25: 0 | GT25: 0 | GU25: 0 | GV25: 0 | GW25: 0 | GX25: 0 | GY25: 0 | GZ25: 0 | HA25: 0 | HB25: 0 | HC25: 0 | HD25: 0 | HE25: 0 | HF25: 0 | HG25: 0 | HH25: 0 | HI25: 0 | HJ25: 0 | HK25: 0 | HL25: 0 | HM25: 0 | HN25: 0 | HO25: 0 | HP25: 0 | HQ25: 0 | HR25: 0 | HS25: 0 | HT25: 0 | HU25: 0
A26: Stand de Venda - Manutenção | B26: =SUM(C26:AA26) | W26: -34442.6 | X26: -422668.9 | Y26: -260275.15 | Z26: -364851.06 | AA26: -241871.81 | AB26: -456303.01 | AC26: =-66426.55-83395.55 | AE26: =SUM(AG26:HU26) | AG26: -55000 | AH26: -55000 | AI26: -55000 | AJ26: -55000 | AK26: -55000 | AL26: -55000 | AM26: -55000 | AN26: -55000 | AO26: -55000 | AP26: -55000 | AQ26: -55000 | AR26: -55000 | AS26: -55000 | AT26: -55000 | AU26: -55000 | AV26: -55000 | AW26: -55000 | AX26: -55000 | AY26: -55000 | AZ26: -55000 | BA26: -55000 | BB26: -55000 | BC26: -55000 | BD26: -55000 | BE26: -55000 | BF26: -55000 | BG26: -55000 | BH26: -55000 | BI26: -55000 | BJ26: -55000 | BK26: -55000 | BL26: -55000 | BM26: -55000 | BN26: -55000 | BO26: -55000 | BP26: -55000 | BQ26: 0 | BR26: 0 | BS26: 0 | BT26: 0 | BU26: 0 | BV26: 0 | BW26: 0 | BX26: 0 | BY26: 0 | BZ26: 0 | CA26: 0 | CB26: 0 | CC26: 0 | CD26: 0 | CE26: 0 | CF26: 0 | CG26: 0 | CH26: 0 | CI26: 0 | CJ26: 0 | CK26: 0 | CL26: 0 | CM26: 0 | CN26: 0 | CO26: 0 | CP26: 0 | CQ26: 0 | CR26: 0 | CS26: 0 | CT26: 0 | CU26: 0 | CV26: 0 | CW26: 0 | CX26: 0 | CY26: 0 | CZ26: 0 | DA26: 0 | DB26: 0 | DC26: 0 | DD26: 0 | DE26: 0 | DF26: 0 | DG26: 0 | DH26: 0 | DI26: 0 | DJ26: 0 | DK26: 0 | DL26: 0 | DM26: 0 | DN26: 0 | DO26: 0 | DP26: 0 | DQ26: 0 | DR26: 0 | DS26: 0 | DT26: 0 | DU26: 0 | DV26: 0 | DW26: 0 | DX26: 0 | DY26: 0 | DZ26: 0 | EA26: 0 | EB26: 0 | EC26: 0 | ED26: 0 | EE26: 0 | EF26: 0 | EG26: 0 | EH26: 0 | EI26: 0 | EJ26: 0 | EK26: 0 | EL26: 0 | EM26: 0 | EN26: 0 | EO26: 0 | EP26: 0 | EQ26: 0 | ER26: 0 | ES26: 0 | ET26: 0 | EU26: 0 | EV26: 0 | EW26: 0 | EX26: 0 | EY26: 0 | EZ26: 0 | FA26: 0 | FB26: 0 | FC26: 0 | FD26: 0 | FE26: 0 | FF26: 0 | FG26: 0 | FH26: 0 | FI26: 0 | FJ26: 0 | FK26: 0 | FL26: 0 | FM26: 0 | FN26: 0 | FO26: 0 | FP26: 0 | FQ26: 0 | FR26: 0 | FS26: 0 | FT26: 0 | FU26: 0 | FV26: 0 | FW26: 0 | FX26: 0 | FY26: 0 | FZ26: 0 | GA26: 0 | GB26: 0 | GC26: 0 | GD26: 0 | GE26: 0 | GF26: 0 | GG26: 0 | GH26: 0 | GI26: 0 | GJ26: 0 | GK26: 0 | GL26: 0 | GM26: 0 | GN26: 0 | GO26: 0 | GP26: 0 | GQ26: 0 | GR26: 0 | GS26: 0 | GT26: 0 | GU26: 0 | GV26: 0 | GW26: 0 | GX26: 0 | GY26: 0 | GZ26: 0 | HA26: 0 | HB26: 0 | HC26: 0 | HD26: 0 | HE26: 0 | HF26: 0 | HG26: 0 | HH26: 0 | HI26: 0 | HJ26: 0 | HK26: 0 | HL26: 0 | HM26: 0 | HN26: 0 | HO26: 0 | HP26: 0 | HQ26: 0 | HR26: 0 | HS26: 0 | HT26: 0 | HU26: 0
A27: Marketing | B27: =SUM(C27:AA27) | W27: -32159.95 | X27: -30740 | Y27: -18988.62 | Z27: -196816.01 | AA27: -308461.65 | AB27: -387396.3 | AC27: -264220.34 | AE27: =SUM(AG27:HU27) | AG27: -166659.27 | AH27: -166659.27 | AI27: -166659.27 | AJ27: -166659.27 | AK27: -166659.27 | AL27: -166659.27 | AM27: -166659.27 | AN27: -166659.27 | AO27: -166659.27 | AP27: -166659.27 | AQ27: -83329.635 | AR27: -83329.635 | AS27: -83329.635 | AT27: -83329.635 | AU27: -83329.635 | AV27: -83329.635 | AW27: -83329.635 | AX27: -83329.635 | AY27: -83329.635 | AZ27: -83329.635 | BA27: -83329.635 | BB27: -83329.635 | BC27: -83329.635 | BD27: -83329.635 | BE27: -83329.635 | BF27: -83329.635 | BG27: -83329.635 | BH27: -83329.635 | BI27: -83329.635 | BJ27: -83329.635 | BK27: -83329.635 | BL27: -83329.635 | BM27: -83329.635 | BN27: -83329.635 | BO27: -83329.635 | BP27: -83329.635 | BQ27: -83329.635 | BR27: -83329.635 | BS27: -83329.635 | BT27: -83329.635 | BU27: -83329.635 | BV27: -83329.635 | BW27: -83329.635 | BX27: -83329.635 | BY27: -83329.635 | BZ27: -83329.635 | CA27: -83329.635 | CB27: -83329.635 | CC27: -83329.635 | CD27: -83329.635 | CE27: -83329.635 | CF27: -83329.635 | CG27: -83329.635 | CH27: -83329.635 | CI27: -83329.635 | CJ27: -83329.635 | CK27: -83329.635 | CL27: -83329.635 | CM27: -83329.635 | CN27: -83329.635 | CO27: -83329.635 | CP27: -83329.635 | CQ27: -83329.635 | CR27: -83329.635 | CS27: -83329.635 | CT27: -83329.635 | CU27: -83329.635 | CV27: -83329.635 | CW27: -83329.635 | CX27: -83329.635 | CY27: -83329.635 | CZ27: -83329.635 | DA27: -83329.635 | DB27: -83329.635 | DC27: -83329.635 | DD27: -83329.635 | DE27: -83329.635 | DF27: -83329.635 | DG27: -83329.635 | DH27: -83329.635 | DI27: -83329.635 | DJ27: -83329.635 | DK27: -83329.635 | DL27: -83329.635 | DM27: -83329.635 | DN27: -83329.635 | DO27: -83329.635 | DP27: -83329.635 | DQ27: -83329.635 | DR27: -83329.635 | DS27: 0 | DT27: 0 | DU27: 0 | DV27: 0 | DW27: 0 | DX27: 0 | DY27: 0 | DZ27: 0 | EA27: 0 | EC27: 0 | ED27: 0 | EE27: 0 | EF27: 0 | EG27: 0 | EH27: 0 | EI27: 0 | EJ27: 0 | EK27: 0 | EL27: 0 | EM27: 0 | EN27: 0 | EO27: 0 | EP27: 0 | EQ27: 0 | ER27: 0 | ES27: 0 | ET27: 0 | EU27: 0 | EV27: 0 | EW27: 0 | EX27: 0 | EY27: 0 | EZ27: 0 | FA27: 0 | FB27: 0 | FC27: 0 | FD27: 0 | FE27: 0 | FF27: 0 | FG27: 0 | FH27: 0 | FI27: 0 | FJ27: 0 | FK27: 0 | FL27: 0 | FM27: 0 | FN27: 0 | FO27: 0 | FP27: 0 | FQ27: 0 | FR27: 0 | FS27: 0 | FT27: 0 | FU27: 0 | FV27: 0 | FW27: 0 | FX27: 0 | FY27: 0 | FZ27: 0 | GA27: 0 | GB27: 0 | GC27: 0 | GD27: 0 | GE27: 0 | GF27: 0 | GG27: 0 | GH27: 0 | GI27: 0 | GJ27: 0 | GK27: 0 | GL27: 0 | GM27: 0 | GN27: 0 | GO27: 0 | GP27: 0 | GQ27: 0 | GR27: 0 | GS27: 0 | GT27: 0 | GU27: 0 | GV27: 0 | GW27: 0 | GX27: 0 | GY27: 0 | GZ27: 0 | HA27: 0 | HB27: 0 | HC27: 0 | HD27: 0 | HE27: 0 | HF27: 0 | HG27: 0 | HH27: 0 | HI27: 0 | HJ27: 0 | HK27: 0 | HL27: 0 | HM27: 0 | HN27: 0 | HO27: 0 | HP27: 0 | HQ27: 0 | HR27: 0 | HS27: 0 | HT27: 0 | HU27: 0
A28: Salário Fixo | B28: =SUM(C28:AA28) | AC28: -228.84 | AE28: =SUM(AG28:HU28) | DL28: 0 | DM28: 0 | DN28: 0 | DO28: 0 | DP28: 0 | DQ28: 0 | DR28: 0 | DS28: 0 | DT28: 0 | DU28: 0 | DV28: 0 | DW28: 0 | DX28: 0 | DY28: 0 | DZ28: 0 | EA28: 0 | EB28: 0 | EC28: 0 | ED28: 0 | EE28: 0 | EF28: 0 | EG28: 0 | EH28: 0 | EI28: 0 | EJ28: 0 | EK28: 0 | EL28: 0 | EM28: 0 | EN28: 0 | EO28: 0 | EP28: 0 | EQ28: 0 | ER28: 0 | ES28: 0 | ET28: 0 | EU28: 0 | EV28: 0 | EW28: 0 | EX28: 0 | EY28: 0 | EZ28: 0 | FA28: 0 | FB28: 0 | FC28: 0 | FD28: 0 | FE28: 0 | FF28: 0 | FG28: 0 | FH28: 0 | FI28: 0 | FJ28: 0 | FK28: 0 | FL28: 0 | FM28: 0 | FN28: 0 | FO28: 0 | FP28: 0 | FQ28: 0 | FR28: 0 | FS28: 0 | FT28: 0 | FU28: 0 | FV28: 0 | FW28: 0 | FX28: 0 | FY28: 0 | FZ28: 0 | GA28: 0 | GB28: 0 | GC28: 0 | GD28: 0 | GE28: 0 | GF28: 0 | GG28: 0 | GH28: 0 | GI28: 0 | GJ28: 0 | GK28: 0 | GL28: 0 | GM28: 0 | GN28: 0 | GO28: 0 | GP28: 0 | GQ28: 0 | GR28: 0 | GS28: 0 | GT28: 0 | GU28: 0 | GV28: 0 | GW28: 0 | GX28: 0 | GY28: 0 | GZ28: 0 | HA28: 0 | HB28: 0 | HC28: 0 | HD28: 0 | HE28: 0 | HF28: 0 | HG28: 0 | HH28: 0 | HI28: 0 | HJ28: 0 | HK28: 0 | HL28: 0 | HM28: 0 | HN28: 0 | HO28: 0 | HP28: 0 | HQ28: 0 | HR28: 0 | HS28: 0 | HT28: 0 | HU28: 0
A29: Subtotal | B29: =SUM(C29:W29) | C29: =SUM(C25:C28) | D29: =SUM(D25:D28) | E29: =SUM(E25:E28) | F29: =SUM(F25:F28) | G29: =SUM(G25:G28) | H29: =SUM(H25:H28) | I29: =SUM(I25:I28) | J29: =SUM(J25:J28) | ... AC29: =SUM(AC25:AC28) | AE29: =SUM(AG29:DN29) | AG29: =SUM(AG25:AG28) | AH29: =SUM(AH25:AH28) | AI29: =SUM(AI25:AI28) | AJ29: =SUM(AJ25:AJ28) | AK29: =SUM(AK25:AK28) | AL29: =SUM(AL25:AL28) | AM29: =SUM(AM25:AM28) | AN29: =SUM(AN25:AN28) | ... HU29: =SUM(HU25:HU28)
A31: ITBI + IPTU ESTOQUE(-)
A32: ITBI | B32: =SUM(C32:X32) | AE32: =SUM(AG32:HU32) | AG32: 0 | AJ32: 0 | AK32: 0 | AL32: 0 | AM32: 0 | AN32: 0 | AO32: 0 | AP32: 0 | AQ32: 0 | AR32: 0 | AS32: 0 | AT32: 0 | AU32: 0 | AV32: 0 | AW32: 0 | AX32: 0 | AY32: 0 | AZ32: 0 | BA32: 0 | BB32: 0 | BC32: 0 | BD32: 0 | BE32: 0 | BF32: 0 | BG32: 0 | BH32: 0 | BI32: 0 | BJ32: 0 | BK32: 0 | BL32: 0 | BM32: 0 | BN32: 0 | BO32: 0 | BP32: 0 | BQ32: 0 | BR32: 0 | BS32: 0 | BT32: 0 | BU32: 0 | BV32: 0 | BW32: 0 | BX32: 0 | BY32: 0 | BZ32: 0 | CA32: 0 | CB32: 0 | CC32: 0 | CD32: 0 | CE32: 0 | CF32: 0 | CG32: 0 | CH32: 0 | CI32: 0 | CJ32: 0 | CK32: 0 | CL32: 0 | CM32: 0 | CN32: 0 | CO32: 0 | CP32: 0 | CQ32: 0 | CR32: 0 | CS32: 0 | CT32: 0 | CU32: 0 | CV32: 0 | CW32: 0 | CX32: 0 | CY32: 0 | CZ32: 0 | DA32: 0 | DB32: 0 | DC32: 0 | DD32: 0 | DE32: 0 | DF32: 0 | DG32: 0 | DH32: 0 | DI32: 0 | DJ32: 0 | DL32: 0 | DM32: 0 | DN32: 0 | DO32: 0 | DP32: 0 | DQ32: 0 | DR32: 0 | DS32: 0 | DT32: 0 | DU32: 0 | DV32: 0 | DW32: 0 | DX32: 0 | DY32: 0 | DZ32: 0 | EA32: 0 | EB32: 0 | EC32: 0 | ED32: 0 | EE32: 0 | EF32: 0 | EG32: 0 | EH32: 0 | EI32: 0 | EJ32: 0 | EK32: 0 | EL32: 0 | EM32: 0 | EN32: 0 | EO32: 0 | EP32: 0 | EQ32: 0 | ER32: 0 | ES32: 0 | ET32: 0 | EU32: 0 | EV32: 0 | EW32: 0 | EX32: 0 | EY32: 0 | EZ32: 0 | FA32: 0 | FB32: 0 | FC32: 0 | FD32: 0 | FE32: 0 | FF32: 0 | FG32: 0 | FH32: 0 | FI32: 0 | FJ32: 0 | FK32: 0 | FL32: 0 | FM32: 0 | FN32: 0 | FO32: 0 | FP32: 0 | FQ32: 0 | FR32: 0 | FS32: 0 | FT32: 0 | FU32: 0 | FV32: 0 | FW32: 0 | FX32: 0 | FY32: 0 | FZ32: 0 | GA32: 0 | GB32: 0 | GC32: 0 | GD32: 0 | GE32: 0 | GF32: 0 | GG32: 0 | GH32: 0 | GI32: 0 | GJ32: 0 | GK32: 0 | GL32: 0 | GM32: 0 | GN32: 0 | GO32: 0 | GP32: 0 | GQ32: 0 | GR32: 0 | GS32: 0 | GT32: 0 | GU32: 0 | GV32: 0 | GW32: 0 | GX32: 0 | GY32: 0 | GZ32: 0 | HA32: 0 | HB32: 0 | HC32: 0 | HD32: 0 | HE32: 0 | HF32: 0 | HG32: 0 | HH32: 0 | HI32: 0 | HJ32: 0 | HK32: 0 | HL32: 0 | HM32: 0 | HN32: 0 | HO32: 0 | HP32: 0 | HQ32: 0 | HR32: 0 | HS32: 0 | HT32: 0 | HU32: 0
A33: IPTU Estoque | B33: =SUM(C33:X33) | AE33: =SUM(AG33:HU33) | AG33: 0 | AH33: 0 | AI33: 0 | AJ33: 0 | AK33: 0 | AL33: 0 | AM33: 0 | AN33: 0 | AO33: 0 | AP33: 0 | AQ33: 0 | AR33: 0 | AS33: 0 | AT33: 0 | AU33: 0 | AV33: 0 | AW33: 0 | AX33: 0 | AY33: 0 | AZ33: 0 | BA33: 0 | BB33: 0 | BC33: 0 | BD33: 0 | BE33: 0 | BF33: 0 | BG33: 0 | BH33: 0 | BI33: 0 | BJ33: 0 | BK33: 0 | BL33: 0 | BM33: 0 | BN33: 0 | BO33: 0 | BP33: 0 | BQ33: 0 | BR33: 0 | BS33: 0 | BT33: 0 | BU33: 0 | BV33: 0 | BW33: 0 | BX33: 0 | BY33: 0 | BZ33: 0 | CA33: 0 | CB33: 0 | CC33: 0 | CD33: 0 | CE33: 0 | CF33: 0 | CG33: 0 | CH33: 0 | CI33: 0 | CJ33: 0 | CK33: 0 | CL33: 0 | CM33: 0 | CN33: 0 | CO33: 0 | CP33: 0 | CQ33: 0 | CR33: 0 | CS33: 0 | CT33: 0 | CU33: 0 | CV33: 0 | CW33: 0 | CX33: 0 | CY33: 0 | CZ33: 0 | DA33: 0 | DB33: 0 | DC33: 0 | DD33: 0 | DE33: 0 | DF33: 0 | DG33: 0 | DH33: 0 | DI33: 0 | DJ33: 0 | DL33: 0 | DM33: 0 | DN33: 0 | DO33: 0 | DP33: 0 | DQ33: 0 | DR33: 0 | DS33: 0 | DT33: 0 | DU33: 0 | DV33: 0 | DW33: 0 | DX33: 0 | DY33: 0 | DZ33: 0 | EA33: 0 | EB33: 0 | EC33: 0 | ED33: 0 | EE33: 0 | EF33: 0 | EG33: 0 | EH33: 0 | EI33: 0 | EJ33: 0 | EK33: 0 | EL33: 0 | EM33: 0 | EN33: 0 | EO33: 0 | EP33: 0 | EQ33: 0 | ER33: 0 | ES33: 0 | ET33: 0 | EU33: 0 | EV33: 0 | EW33: 0 | EX33: 0 | EY33: 0 | EZ33: 0 | FA33: 0 | FB33: 0 | FC33: 0 | FD33: 0 | FE33: 0 | FF33: 0 | FG33: 0 | FH33: 0 | FI33: 0 | FJ33: 0 | FK33: 0 | FL33: 0 | FM33: 0 | FN33: 0 | FO33: 0 | FP33: 0 | FQ33: 0 | FR33: 0 | FS33: 0 | FT33: 0 | FU33: 0 | FV33: 0 | FW33: 0 | FX33: 0 | FY33: 0 | FZ33: 0 | GA33: 0 | GB33: 0 | GC33: 0 | GD33: 0 | GE33: 0 | GF33: 0 | GG33: 0 | GH33: 0 | GI33: 0 | GJ33: 0 | GK33: 0 | GL33: 0 | GM33: 0 | GN33: 0 | GO33: 0 | GP33: 0 | GQ33: 0 | GR33: 0 | GS33: 0 | GT33: 0 | GU33: 0 | GV33: 0 | GW33: 0 | GX33: 0 | GY33: 0 | GZ33: 0 | HA33: 0 | HB33: 0 | HC33: 0 | HD33: 0 | HE33: 0 | HF33: 0 | HG33: 0 | HH33: 0 | HI33: 0 | HJ33: 0 | HK33: 0 | HL33: 0 | HM33: 0 | HN33: 0 | HO33: 0 | HP33: 0 | HQ33: 0 | HR33: 0 | HS33: 0 | HT33: 0 | HU33: 0
A34: Subtotal | B34: =SUM(C34:W34) | C34: =SUM(C32:C33) | D34: =SUM(D32:D33) | E34: =SUM(E32:E33) | F34: =SUM(F32:F33) | G34: =SUM(G32:G33) | H34: =SUM(H32:H33) | I34: =SUM(I32:I33) | J34: =SUM(J32:J33) | ... R34: =SUM(R32:R33) | T34: =SUM(T32:T33) | U34: =SUM(U32:U33) | V34: =SUM(V32:V33) | W34: =SUM(W32:W33) | X34: =SUM(X32:X33) | Y34: =SUM(Y32:Y33) | Z34: =SUM(Z32:Z33) | AA34: =SUM(AA32:AA33) | ... AC34: =SUM(AC32:AC33) | AE34: =SUM(AG34:DU34) | AG34: =SUM(AG32:AG33) | AH34: =SUM(AH32:AH33) | AI34: =SUM(AI32:AI33) | AJ34: =SUM(AJ32:AJ33) | AK34: =SUM(AK32:AK33) | AL34: =SUM(AL32:AL33) | AM34: =SUM(AM32:AM33) | AN34: =SUM(AN32:AN33) | ... DJ34: =SUM(DJ32:DJ33) | DL34: =SUM(DL32:DL33) | DM34: =SUM(DM32:DM33) | DN34: =SUM(DN32:DN33) | DO34: =SUM(DO32:DO33) | DP34: =SUM(DP32:DP33) | DQ34: =SUM(DQ32:DQ33) | DR34: =SUM(DR32:DR33) | DS34: =SUM(DS32:DS33) | ... HU34: =SUM(HU32:HU33)
A36: DESPESAS DE OBRA (-) | Projeto (-)
A37: OBRA - (PREVISTO VIABIL) | B37: =SUM(C37:AA37) | AC37: -124003.31 | AE37: =SUM(AG37:HU37) | AG37: 0 | AH37: -1100768.2 | AI37: -1273700.1 | AJ37: -1264677.5 | AK37: -1137609.4 | AL37: -1140768.2 | AM37: -1100768.2 | AN37: -1452653.1 | AO37: -1317312.8 | AP37: -2156423 | AQ37: -2409058.3 | AR37: -2950419.7 | AS37: -3103805.5 | AT37: -3076737.4 | AU37: -1578970.8 | AV37: -1227085.9 | AW37: -1001518.6 | AX37: -2769965.9 | AY37: -4015097.2 | AZ37: -6198588.2 | BA37: -5945952.9 | BB37: -5846703.3 | BC37: -5855726 | BD37: -6640700.1 | BE37: -6496337 | BF37: -3717348.4 | BG37: -1046632.1 | BH37: -1046632.1 | BI37: -1046632.1 | BJ37: -1181972.4 | BK37: -1181972.4 | BL37: -1506789.3 | BM37: -1569948.1 | BN37: -2048150.7 | BO37: -2048150.7 | BP37: -1578970.8 | BQ37: -1732356.5 | BR37: -54512.651 | BS37: -54512.651 | BT37: -54512.651 | BU37: -54512.651 | BV37: -54512.651 | BW37: -54512.651 | BX37: -54512.651 | BY37: -54512.651 | BZ37: -54512.651 | CA37: -54512.651 | CB37: -54512.651 | CC37: -54512.651 | CD37: -54512.651 | CE37: -54512.651 | CF37: -54512.651 | CG37: -54512.651 | CH37: -54512.651 | CI37: -54512.651 | CJ37: -54512.651 | CK37: -54512.651 | CL37: -54512.651 | CM37: -54512.651 | CN37: -54512.651 | CO37: -54512.651 | CP37: 0 | CQ37: 0 | CR37: 0 | CS37: 0 | CT37: 0 | CU37: 0 | CV37: 0 | CW37: 0 | CX37: 0 | CY37: 0 | CZ37: 0 | DA37: 0 | DB37: 0 | DC37: 0 | DD37: 0 | DE37: 0 | DF37: 0 | DG37: 0 | DH37: 0 | DI37: 0 | DJ37: 0 | DK37: 0 | DL37: 0 | DM37: 0 | DN37: 0 | DO37: 0 | DP37: 0 | DQ37: 0 | DR37: 0 | DS37: 0 | DT37: 0 | DU37: 0 | DV37: 0 | DW37: 0 | DX37: 0 | DY37: 0 | DZ37: 0 | EA37: 0 | EB37: 0 | EC37: 0 | ED37: 0 | EE37: 0 | EF37: 0 | EG37: 0 | EH37: 0 | EI37: 0 | EJ37: 0 | EK37: 0 | EL37: 0 | EM37: 0 | EN37: 0 | EO37: 0 | EP37: 0 | EQ37: 0 | ER37: 0 | ES37: 0 | ET37: 0 | EU37: 0 | EV37: 0 | EW37: 0 | EX37: 0 | EY37: 0 | EZ37: 0 | FA37: 0 | FB37: 0 | FC37: 0 | FD37: 0 | FE37: 0 | FF37: 0 | FG37: 0 | FH37: 0 | FI37: 0 | FJ37: 0 | FK37: 0 | FL37: 0 | FM37: 0 | FN37: 0 | FO37: 0 | FP37: 0 | FQ37: 0 | FR37: 0 | FS37: 0 | FT37: 0 | FU37: 0 | FV37: 0 | FW37: 0 | FX37: 0 | FY37: 0 | FZ37: 0 | GA37: 0 | GB37: 0 | GC37: 0 | GD37: 0 | GE37: 0 | GF37: 0 | GG37: 0 | GH37: 0 | GI37: 0 | GJ37: 0 | GK37: 0 | GL37: 0 | GM37: 0 | GN37: 0 | GO37: 0 | GP37: 0 | GQ37: 0 | GR37: 0 | GS37: 0 | GT37: 0 | GU37: 0 | GV37: 0 | GW37: 0 | GX37: 0 | GY37: 0 | GZ37: 0 | HA37: 0 | HB37: 0 | HC37: 0 | HD37: 0 | HE37: 0 | HF37: 0 | HG37: 0 | HH37: 0 | HI37: 0 | HJ37: 0 | HK37: 0 | HL37: 0 | HM37: 0 | HN37: 0 | HO37: 0 | HP37: 0 | HQ37: 0 | HR37: 0 | HS37: 0 | HT37: 0 | HU37: 0
A38: CONTRAPARTIDA SAAE | AE38: =SUM(AG38:HU38) | AG38: 0 | AH38: 0 | AI38: 0 | AJ38: 0 | AK38: 0 | AL38: 0 | AM38: 0 | AN38: 0 | AO38: 0 | AP38: 0 | AQ38: 0 | AR38: 0 | AS38: 0 | AT38: 0 | AU38: 0 | AV38: 0 | AW38: 0 | AX38: 0 | AY38: -66666.667 | AZ38: -66666.667 | BA38: -66666.667 | BB38: -66666.667 | BC38: -66666.667 | BD38: -66666.667 | BE38: -66666.667 | BF38: -66666.667 | BG38: -66666.667 | BH38: -66666.667 | BI38: -66666.667 | BJ38: -66666.667 | BK38: -66666.667 | BL38: -66666.667 | BM38: -66666.667 | BN38: -66666.667 | BO38: -66666.667 | BP38: -66666.667 | BQ38: 0 | BR38: 0 | BS38: 0 | BT38: 0 | BU38: 0 | BV38: 0 | BW38: 0 | BX38: 0 | BY38: 0 | BZ38: 0 | CA38: 0 | CB38: 0 | CC38: 0 | CD38: 0 | CE38: 0 | CF38: 0 | CG38: 0 | CH38: 0 | CI38: 0 | CJ38: 0 | CK38: 0 | CL38: 0 | CM38: 0 | CN38: 0 | CO38: 0 | CP38: 0 | CQ38: 0 | CR38: 0 | CS38: 0 | CT38: 0 | CU38: 0 | CV38: 0 | CW38: 0 | CX38: 0 | CY38: 0 | CZ38: 0 | DA38: 0 | DB38: 0 | DC38: 0 | DD38: 0 | DE38: 0 | DF38: 0 | DG38: 0 | DH38: 0 | DI38: 0 | DJ38: 0 | DK38: 0 | DL38: 0 | DM38: 0 | DN38: 0 | DO38: 0 | DP38: 0 | DQ38: 0 | DR38: 0 | DS38: 0 | DT38: 0 | DU38: 0 | DV38: 0 | DW38: 0 | DX38: 0 | DY38: 0 | DZ38: 0 | EA38: 0 | EB38: 0 | EC38: 0 | ED38: 0 | EE38: 0 | EF38: 0 | EG38: 0 | EH38: 0 | EI38: 0 | EJ38: 0 | EK38: 0 | EL38: 0 | EM38: 0 | EN38: 0 | EO38: 0 | EP38: 0 | EQ38: 0 | ER38: 0 | ES38: 0 | ET38: 0 | EU38: 0 | EV38: 0 | EW38: 0 | EX38: 0 | EY38: 0 | EZ38: 0 | FA38: 0 | FB38: 0 | FC38: 0 | FD38: 0 | FE38: 0 | FF38: 0 | FG38: 0 | FH38: 0 | FI38: 0 | FJ38: 0 | FK38: 0 | FL38: 0 | FM38: 0 | FN38: 0 | FO38: 0 | FP38: 0 | FQ38: 0 | FR38: 0 | FS38: 0 | FT38: 0 | FU38: 0 | FV38: 0 | FW38: 0 | FX38: 0 | FY38: 0 | FZ38: 0 | GA38: 0 | GB38: 0 | GC38: 0 | GD38: 0 | GE38: 0 | GF38: 0 | GG38: 0 | GH38: 0 | GI38: 0 | GJ38: 0 | GK38: 0 | GL38: 0 | GM38: 0 | GN38: 0 | GO38: 0 | GP38: 0 | GQ38: 0 | GR38: 0 | GS38: 0 | GT38: 0 | GU38: 0 | GV38: 0 | GW38: 0 | GX38: 0 | GY38: 0 | GZ38: 0 | HA38: 0 | HB38: 0 | HC38: 0 | HD38: 0 | HE38: 0 | HF38: 0 | HG38: 0 | HH38: 0 | HI38: 0 | HJ38: 0 | HK38: 0 | HL38: 0 | HM38: 0 | HN38: 0 | HO38: 0 | HP38: 0 | HQ38: 0 | HR38: 0 | HS38: 0 | HT38: 0 | HU38: 0
A40: INCORPORAÇÃO (-)
A41: Incorporação | B41: =SUM(C41:X41) | C41: -22569.84 | D41: -66761.36 | E41: -22685 | F41: -22753.06 | G41: -22784.91 | H41: -25995.64 | I41: -23082.07 | J41: -23105.15 | K41: -28144.43 | L41: -28223.13 | M41: -28269.57 | N41: -28285.85 | O41: -30358.04 | P41: -28421.11 | Q41: -51733.24 | R41: -57539.95 | S41: -30362.5 | T41: -56077.16 | U41: -30362.5 | V41: -98850 | W41: -36362.5 | X41: -645250.94 | Y41: -280557.39 | Z41: -29760.76 | AA41: =(-184611.43)+-24760.76 | AB41: -90439.16 | AC41: =-49101.24-49521.52 | AE41: =SUM(AG41:HU41) | AG41: -33000 | AH41: -33000 | AI41: -33000 | AJ41: -33000 | AK41: -8000 | AL41: -8000 | AM41: -8000 | AN41: -8000 | AO41: -8000 | AP41: -8000 | AQ41: -8000 | AR41: -8000 | AS41: -8000 | AT41: -8000 | AU41: -8000 | AV41: -8000 | AW41: -8000 | AX41: -8000 | AY41: -8000 | AZ41: -8000 | BA41: -8000 | BB41: -8000 | BC41: -8000 | BD41: -8000 | BE41: -8000 | BF41: -8000 | BG41: -8000 | BH41: -8000 | BI41: -8000 | BJ41: -8000 | BK41: -8000 | BL41: -8000 | BM41: -8000 | BN41: -3000 | BO41: -3000 | BP41: -3000 | BQ41: -3000 | BR41: -3000 | DY41: 0 | DZ41: 0 | EA41: 0 | EB41: 0 | EC41: 0 | ED41: 0 | EE41: 0 | EF41: 0 | EG41: 0 | EH41: 0 | EI41: 0 | EJ41: 0 | EK41: 0 | EL41: 0 | EM41: 0 | EN41: 0 | EO41: 0 | EP41: 0 | EQ41: 0 | ER41: 0 | ES41: 0 | ET41: 0 | EU41: 0 | EV41: 0 | EW41: 0 | EX41: 0 | EY41: 0 | EZ41: 0 | FA41: 0 | FB41: 0 | FC41: 0 | FD41: 0 | FE41: 0 | FF41: 0 | FG41: 0 | FH41: 0 | FI41: 0 | FJ41: 0 | FK41: 0 | FL41: 0 | FM41: 0 | FN41: 0 | FO41: 0 | FP41: 0 | FQ41: 0 | FR41: 0 | FS41: 0 | FT41: 0 | FU41: 0 | FV41: 0 | FW41: 0 | FX41: 0 | FY41: 0 | FZ41: 0 | GA41: 0 | GB41: 0 | GC41: 0 | GD41: 0 | GE41: 0 | GF41: 0 | GG41: 0 | GH41: 0 | GI41: 0 | GJ41: 0 | GK41: 0 | GL41: 0 | GM41: 0 | GN41: 0 | GO41: 0 | GP41: 0 | GQ41: 0 | GR41: 0 | GS41: 0 | GT41: 0 | GU41: 0 | GV41: 0 | GW41: 0 | GX41: 0 | GY41: 0 | GZ41: 0 | HA41: 0 | HB41: 0 | HC41: 0 | HD41: 0 | HE41: 0 | HF41: 0 | HG41: 0 | HH41: 0 | HI41: 0 | HJ41: 0 | HK41: 0 | HL41: 0 | HM41: 0 | HN41: 0 | HO41: 0 | HP41: 0 | HQ41: 0 | HR41: 0 | HS41: 0 | HT41: 0 | HU41: 0
A42: Gerenciamento | AE42: =SUM(AG42:HU42) | AG42: -8000 | AH42: -8000 | AI42: -8000 | AJ42: -8000 | AK42: -8000 | AL42: -8000 | AM42: -8000 | AN42: -8000 | AO42: -8000 | AP42: -8000 | AQ42: -8000 | AR42: -8000 | AS42: -8000 | AT42: -8000 | AU42: -8000 | AV42: -8000 | AW42: -8000 | AX42: -8000 | AY42: -8000 | AZ42: -8000 | BA42: -8000 | BB42: -8000 | BC42: -8000 | BD42: -8000 | BE42: -8000 | BF42: -8000 | BG42: -8000 | BH42: -8000 | BI42: -8000 | BJ42: -8000 | BK42: -8000 | BL42: -8000 | BM42: -8000 | BN42: -8000 | BO42: -8000 | BP42: -8000 | BQ42: -8000 | BR42: -8000 | BS42: -8000 | BT42: -8000 | BU42: -8000 | BV42: -8000 | BW42: -8000 | BX42: -8000 | BY42: -8000 | BZ42: -8000 | CA42: -8000 | CB42: -8000 | CC42: -8000 | CD42: -8000 | CE42: -8000 | CF42: -8000 | CG42: -8000 | CH42: -8000 | CI42: -8000 | CJ42: -8000 | CK42: -8000 | CL42: -8000 | CM42: -8000 | CN42: -8000 | DY42: 0 | DZ42: 0 | EA42: 0 | EB42: 0 | EC42: 0 | ED42: 0 | EE42: 0 | EF42: 0 | EG42: 0 | EH42: 0 | EI42: 0 | EJ42: 0 | EK42: 0 | EL42: 0 | EM42: 0 | EN42: 0 | EO42: 0 | EP42: 0 | EQ42: 0 | ER42: 0 | ES42: 0 | ET42: 0 | EU42: 0 | EV42: 0 | EW42: 0 | EX42: 0 | EY42: 0 | EZ42: 0 | FA42: 0 | FB42: 0 | FC42: 0 | FD42: 0 | FE42: 0 | FF42: 0 | FG42: 0 | FH42: 0 | FI42: 0 | FJ42: 0 | FK42: 0 | FL42: 0 | FM42: 0 | FN42: 0 | FO42: 0 | FP42: 0 | FQ42: 0 | FR42: 0 | FS42: 0 | FT42: 0 | FU42: 0 | FV42: 0 | FW42: 0 | FX42: 0 | FY42: 0 | FZ42: 0 | GA42: 0 | GB42: 0 | GC42: 0 | GD42: 0 | GE42: 0 | GF42: 0 | GG42: 0 | GH42: 0 | GI42: 0 | GJ42: 0 | GK42: 0 | GL42: 0 | GM42: 0 | GN42: 0 | GO42: 0 | GP42: 0 | GQ42: 0 | GR42: 0 | GS42: 0 | GT42: 0 | GU42: 0 | GV42: 0 | GW42: 0 | GX42: 0 | GY42: 0 | GZ42: 0 | HA42: 0 | HB42: 0 | HC42: 0 | HD42: 0 | HE42: 0 | HF42: 0 | HG42: 0 | HH42: 0 | HI42: 0 | HJ42: 0 | HK42: 0 | HL42: 0 | HM42: 0 | HN42: 0 | HO42: 0 | HP42: 0 | HQ42: 0 | HR42: 0 | HS42: 0 | HT42: 0 | HU42: 0
A44: DESPESAS JÚRIDICAS (-)
A45: Despesas juridicas | B45: =SUM(C45:X45) | AE45: =SUM(AG45:HU45) | AG45: 0 | AH45: 0 | AI45: 0 | AJ45: 0 | AK45: 0 | AL45: 0 | AM45: 0 | AN45: 0 | AO45: 0 | AP45: 0 | AQ45: 0 | AR45: 0 | AS45: 0 | AT45: 0 | AU45: 0 | AV45: 0 | AW45: 0 | AX45: 0 | AY45: 0 | AZ45: 0 | BA45: 0 | BB45: 0 | BC45: 0 | BD45: 0 | BE45: 0 | BF45: 0 | BG45: 0 | BH45: 0 | BI45: 0 | BJ45: 0 | BK45: 0 | BL45: 0 | BM45: 0 | BN45: 0 | BO45: 0 | BP45: 0 | BQ45: 0 | BR45: 0 | BS45: 0 | BT45: 0 | BU45: 0 | BV45: 0 | BW45: 0 | BX45: 0 | BY45: 0 | BZ45: 0 | CA45: 0 | CB45: 0 | CC45: 0 | CD45: 0 | CE45: 0 | CF45: 0 | CG45: 0 | CH45: 0 | CI45: 0 | CJ45: 0 | CK45: 0 | CL45: 0 | CM45: 0 | CN45: 0 | CO45: 0 | CP45: 0 | CQ45: 0 | CR45: 0 | CS45: 0 | CT45: 0 | CU45: 0 | CV45: 0 | CW45: 0 | CX45: 0 | CY45: 0 | CZ45: 0 | DA45: 0 | DB45: 0 | DC45: 0 | DD45: 0 | DE45: 0 | DF45: 0 | DG45: 0 | DH45: 0 | DI45: 0 | DJ45: 0 | DK45: 0 | DL45: 0 | DM45: 0 | DN45: 0 | DO45: 0 | DP45: 0 | DQ45: 0 | DR45: 0 | DS45: 0 | DT45: 0 | DU45: 0 | DV45: 0 | DW45: 0 | DX45: 0 | DY45: 0 | DZ45: 0 | EA45: 0 | EB45: 0 | EC45: 0 | ED45: 0 | EE45: 0 | EF45: 0 | EG45: 0 | EH45: 0 | EI45: 0 | EJ45: 0 | EK45: 0 | EL45: 0 | EM45: 0 | EN45: 0 | EO45: 0 | EP45: 0 | EQ45: 0 | ER45: 0 | ES45: 0 | ET45: 0 | EU45: 0 | EV45: 0 | EW45: 0 | EX45: 0 | EY45: 0 | EZ45: 0 | FA45: 0 | FB45: 0 | FC45: 0 | FD45: 0 | FE45: 0 | FF45: 0 | FG45: 0 | FH45: 0 | FI45: 0 | FJ45: 0 | FK45: 0 | FL45: 0 | FM45: 0 | FN45: 0 | FO45: 0 | FP45: 0 | FQ45: 0 | FR45: 0 | FS45: 0 | FT45: 0 | FU45: 0 | FV45: 0 | FW45: 0 | FX45: 0 | FY45: 0 | FZ45: 0 | GA45: 0 | GB45: 0 | GC45: 0 | GD45: 0 | GE45: 0 | GF45: 0 | GG45: 0 | GH45: 0 | GI45: 0 | GJ45: 0 | GK45: 0 | GL45: 0 | GM45: 0 | GN45: 0 | GO45: 0 | GP45: 0 | GQ45: 0 | GR45: 0 | GS45: 0 | GT45: 0 | GU45: 0 | GV45: 0 | GW45: 0 | GX45: 0 | GY45: 0 | GZ45: 0 | HA45: 0 | HB45: 0 | HC45: 0 | HD45: 0 | HE45: 0 | HF45: 0 | HG45: 0 | HH45: 0 | HI45: 0 | HJ45: 0 | HK45: 0 | HL45: 0 | HM45: 0 | HN45: 0 | HO45: 0 | HP45: 0 | HQ45: 0 | HR45: 0 | HS45: 0 | HT45: 0 | HU45: 0
A47: OUTRAS DESPESAS (-)
A48: Outras Despesas (adm) | B48: =SUM(C48:X48) | L48: -1243.93 | O48: -339 | V48: -389 | W48: 0 | X48: -4 | Y48: -1155.21 | Z48: -148.25 | AA48: -344.9 | AB48: -459.58 | AC48: =-26826.58-250 | AE48: =SUM(AG48:HU48) | AG48: -11000 | AH48: -11000 | AI48: -11000 | AJ48: -11000 | AK48: -11000 | AL48: -11000 | AM48: -11000 | AN48: -11000 | AO48: -11000 | AP48: -11000 | AQ48: -11000 | AR48: -11000 | AS48: -11000 | AT48: -11000 | AU48: -11000 | AV48: -11000 | AW48: -11000 | AX48: -11000 | AY48: -11000 | AZ48: -11000 | BA48: -11000 | BB48: -11000 | BC48: -11000 | BD48: -11000 | BE48: -11000 | BF48: -11000 | BG48: -11000 | BH48: -11000 | BI48: -11000 | BJ48: -11000 | BK48: -11000 | BL48: -11000 | BM48: -11000 | BN48: -11000 | BO48: -11000 | BP48: -11000
A50: TOTAL DE DESPESAS OPERACIONAIS (-) | B50: =SUM(C50:W50) | C50: =C48+C45+C41+C37+C34+C29 | D50: =D48+D45+D41+D37+D34+D29 | E50: =E48+E45+E41+E37+E34+E29 | F50: =F48+F45+F41+F37+F34+F29 | G50: =G48+G45+G41+G37+G34+G29 | H50: =H48+H45+H41+H37+H34+H29 | I50: =I48+I45+I41+I37+I34+I29 | J50: =J48+J45+J41+J37+J34+J29 | ... AB50: =AB48+AB45+AB41+AB37+AB34+AB29 | AC50: =AC48+AC45+AC41+AC37+AC34+AC29+AC42 | AE50: =SUM(AG50:DN50) | AG50: =AG48+AG45+AG41+AG37+AG34+AG29+AG42+AG38 | AH50: =AH48+AH45+AH41+AH37+AH34+AH29+AH42+AH38 | AI50: =AI48+AI45+AI41+AI37+AI34+AI29+AI42+AI38 | AJ50: =AJ48+AJ45+AJ41+AJ37+AJ34+AJ29+AJ42+AJ38 | AK50: =AK48+AK45+AK41+AK37+AK34+AK29+AK42+AK38 | AL50: =AL48+AL45+AL41+AL37+AL34+AL29+AL42+AL38 | AM50: =AM48+AM45+AM41+AM37+AM34+AM29+AM42+AM38 | AN50: =AN48+AN45+AN41+AN37+AN34+AN29+AN42+AN38 | ... HU50: =HU48+HU45+HU41+HU37+HU34+HU29+HU42+HU38
A51: TOTAL ACUMULADO DE DESPESAS OP.(-) | B51: =SUM(C51:W51) | D51: =C51+D50 | E51: =D51+E50 | F51: =D51+F50 | G51: =E51+G50 | H51: =F51+H50 | I51: =G51+I50 | J51: =I51+J50 | K51: =J51+K50 | L51: =K51+L50 | M51: =L51+M50 | N51: =M51+N50 | O51: =N51+O50 | P51: =O51+P50 | Q51: =P51+Q50 | ... AC51: =AB51+AC50 | AE51: =W51+AE50 | AG51: =AA51+AG50 | AH51: =AG51+AH50 | AI51: =AH51+AI50 | AJ51: =AI51+AJ50 | AK51: =AJ51+AK50 | AL51: =AK51+AL50 | AM51: =AL51+AM50 | AN51: =AM51+AN50 | AO51: =AN51+AO50 | ... HU51: =HT51+HU50
A53: IMPOSTOS (-)
...

Sheet FC Total (5 lotes)
AR1: Total | Previsão | BF1: PREVISÃO DE | EC1: FIM DAS VENDAS | JF1: Realizado | JM1: Previsão de Maio feita no fechamento de Abril/26 | KH1: Total | Previsão
A2: Ville de Provence | AB2: =+AB8+AB9+AC8+AC9+AD8+AD9+AE8+AE9+AF8+AF9+AD62 | BF2: ENTREGA DA OBRA | JF2: No mês | JG2: Ano 2025 | JH2: Ano 2026 | JI2: Acumulado | JS2: YTD | JT2: Prev. 2025 | JU2: 2026 | JV2: 2027 | JW2: 2028 | JX2: 2029 | JY2: 2030 | JZ2: Demais
C3: 1 | D3: 2 | E3: 3 | F3: 4 | G3: 5 | H3: 6 | I3: 7 | J3: 8 | K3: 9 | L3: 10 | M3: 11 | N3: 12 | O3: 13 | P3: 14 | Q3: 15 | R3: 16 | S3: 17 | T3: 18 | U3: 19 | V3: 20 | W3: 21 | X3: 22 | Y3: 23 | Z3: 24 | AA3: 25 | AB3: 26 | AC3: 27 | AD3: 28 | AE3: 29 | AF3: 30 | AG3: 31 | AH3: 32 | AI3: 33 | AJ3: 34 | AK3: 35 | AL3: 36 | AM3: 37 | AN3: 38 | AO3: 39 | AP3: 40 | AT3: 41 | AU3: 42 | AV3: 43 | AW3: 44 | AX3: 45 | AY3: 46 | AZ3: 47 | BA3: 48 | BB3: 49 | BC3: 50 | BD3: 51 | BE3: 52 | BF3: 53 | BG3: 54 | BH3: 55 | BI3: 56 | BJ3: 57 | BK3: 58 | BL3: 59 | BM3: 60 | BN3: 61 | BO3: 62 | BP3: 63 | BQ3: 64 | BR3: 65 | BS3: 66 | BT3: 67 | BU3: 68 | BV3: 69 | BW3: 70 | BX3: 71 | BY3: 72 | BZ3: 73 | CA3: 74 | CB3: 75 | CC3: 76 | CD3: 77 | CE3: 78 | CF3: 79 | CG3: 80 | CH3: 81 | CI3: 82 | CJ3: 83 | CK3: 84 | CL3: 85 | CM3: 86 | CN3: 87 | CO3: 88 | CP3: 89 | CQ3: 90 | CR3: 91 | CS3: 92 | CT3: 93 | CU3: 94 | CV3: 95 | CW3: 96 | CX3: 97 | CY3: 98 | CZ3: 99 | DA3: 100 | DB3: 101 | DC3: 102 | DD3: 103 | DE3: 104 | DF3: 105 | DG3: 106 | DH3: 107 | DI3: 108 | DJ3: 109 | DK3: 110 | DL3: 111 | DM3: 112 | DN3: 113 | DO3: 114 | DP3: 115 | DQ3: 116 | DR3: 117 | DS3: 118 | DT3: 119 | DU3: 120 | DV3: 121 | DW3: 122 | DX3: 123 | DY3: 124 | DZ3: 125 | EA3: 126 | EB3: 127 | EC3: 128 | ED3: 129 | EE3: 130 | EF3: 131 | EG3: 132 | EH3: 133 | EI3: 134 | EJ3: 135 | EK3: 136 | EL3: 137 | EM3: 138 | EN3: 139 | EO3: 140 | EP3: 141 | EQ3: 142 | ER3: 143 | ES3: 144 | ET3: 145 | EU3: 146 | EV3: 147 | EW3: 148 | EX3: 149 | EY3: 150 | EZ3: 151 | FA3: 152 | FB3: 153 | FC3: 154 | FD3: 155 | FE3: 156 | FF3: 157 | FG3: 158 | FH3: 159 | FI3: 160 | FJ3: 161 | FK3: 162 | FL3: 163 | FM3: 164 | FN3: 165 | FO3: 166 | FP3: 167 | FQ3: 168 | FR3: 169 | FS3: 170 | FT3: 171 | FU3: 172 | FV3: 173 | FW3: 174 | FX3: 175 | FY3: 176 | FZ3: 177 | GA3: 178 | GB3: 179 | GC3: 180 | GD3: 181 | GE3: 182 | GF3: 183 | GG3: 184 | GH3: 185 | GI3: 186 | GJ3: 187 | GK3: 188 | GL3: 189 | GM3: 190 | GN3: 191 | GO3: 192 | GP3: 193 | GQ3: 194 | GR3: 195 | GS3: 196 | GT3: 197 | GU3: 198 | GV3: 199 | GW3: 200 | GX3: 201 | GY3: 202 | GZ3: 203 | HA3: 204 | HB3: 205 | HC3: 206 | HD3: 207 | HE3: 208 | HF3: 209 | HG3: 210 | HH3: 211 | HI3: 212 | HJ3: 213 | HK3: 214 | HL3: 215 | HM3: 216 | HN3: 217 | HO3: 218 | HP3: 219 | HQ3: 220 | HR3: 221 | HS3: 222 | HT3: 223 | HU3: 224 | JM3: 40
A4: Fluxo de Caixa | B4: REALIZADO | M4: REALIZADO | KG4: REALIZADO
C5: 44958 | D5: 44986 | E5: 45017 | F5: 45047 | G5: 45078 | H5: 45108 | I5: 45139 | J5: 45170 | K5: 45200 | L5: 45231 | M5: 45261 | N5: 45292 | O5: 45323 | P5: 45352 | Q5: 45383 | R5: 45413 | S5: 45444 | T5: 45474 | U5: 45505 | V5: 45536 | W5: 45566 | X5: 45597 | Y5: 45627 | Z5: 45658 | AA5: 45689 | AB5: 45717 | AC5: 45748 | AD5: 45778 | AE5: 45809 | AF5: 45839 | AG5: 45870 | AH5: 45901 | AI5: 45931 | AJ5: 45962 | AK5: 45992 | AL5: 46023 | AM5: 46054 | AN5: 46082 | AO5: 46113 | AP5: 46143 | AR5: Total | Previsão | AT5: 46174 | AU5: 46204 | AV5: 46235 | AW5: 46266 | AX5: 46296 | AY5: 46327 | AZ5: 46357 | BA5: 46388 | BB5: 46419 | BC5: 46447 | BD5: 46478 | BE5: 46508 | BF5: 46539 | BG5: 46569 | BH5: 46600 | BI5: 46631 | BJ5: 46661 | BK5: 46692 | BL5: 46722 | BM5: 46753 | BN5: 46784 | BO5: 46813 | BP5: 46844 | BQ5: 46874 | BR5: 46905 | BS5: 46935 | BT5: 46966 | BU5: 46997 | BV5: 47027 | BW5: 47058 | BX5: 47088 | BY5: 47119 | BZ5: 47150 | CA5: 47178 | CB5: 47209 | CC5: 47239 | CD5: 47270 | CE5: 47300 | CF5: 47331 | CG5: 47362 | CH5: 47392 | CI5: 47423 | CJ5: 47453 | CK5: 47484 | CL5: 47515 | CM5: 47543 | CN5: 47574 | CO5: 47604 | CP5: 47635 | CQ5: 47665 | CR5: 47696 | CS5: 47727 | CT5: 47757 | CU5: 47788 | CV5: 47818 | CW5: 47849 | CX5: 47880 | CY5: 47908 | CZ5: 47939 | DA5: 47969 | DB5: 48000 | DC5: 48030 | DD5: 48061 | DE5: 48092 | DF5: 48122 | DG5: 48153 | DH5: 48183 | DI5: 48214 | DJ5: 48245 | DK5: 48274 | DL5: 48305 | DM5: 48335 | DN5: 48366 | DO5: 48396 | DP5: 48427 | DQ5: 48458 | DR5: 48488 | DS5: 48519 | DT5: 48549 | DU5: 48580 | DV5: 48611 | DW5: 48639 | DX5: 48670 | DY5: 48700 | DZ5: 48731 | EA5: 48761 | EB5: 48792 | EC5: 48823 | ED5: 48853 | EE5: 48884 | EF5: 48914 | EG5: 48945 | EH5: 48976 | EI5: 49004 | EJ5: 49035 | EK5: 49065 | EL5: 49096 | EM5: 49126 | EN5: 49157 | EO5: 49188 | EP5: 49218 | EQ5: 49249 | ER5: 49279 | ES5: 49310 | ET5: 49341 | EU5: 49369 | EV5: 49400 | EW5: 49430 | EX5: 49461 | EY5: 49491 | EZ5: 49522 | FA5: 49553 | FB5: 49583 | FC5: 49614 | FD5: 49644 | FE5: 49675 | FF5: 49706 | FG5: 49735 | FH5: 49766 | FI5: 49796 | FJ5: 49827 | FK5: 49857 | FL5: 49888 | FM5: 49919 | FN5: 49949 | FO5: 49980 | FP5: 50010 | FQ5: 50041 | FR5: 50072 | FS5: 50100 | FT5: 50131 | FU5: 50161 | FV5: 50192 | FW5: 50222 | FX5: 50253 | FY5: 50284 | FZ5: 50314 | GA5: 50345 | GB5: 50375 | GC5: 50406 | GD5: 50437 | GE5: 50465 | GF5: 50496 | GG5: 50526 | GH5: 50557 | GI5: 50587 | GJ5: 50618 | GK5: 50649 | GL5: 50679 | GM5: 50710 | GN5: 50740 | GO5: 50771 | GP5: 50802 | GQ5: 50830 | GR5: 50861 | GS5: 50891 | GT5: 50922 | GU5: 50952 | GV5: 50983 | GW5: 51014 | GX5: 51044 | GY5: 51075 | GZ5: 51105 | HA5: 51136 | HB5: 51167 | HC5: 51196 | HD5: 51227 | HE5: 51257 | HF5: 51288 | HG5: 51318 | HH5: 51349 | HI5: 51380 | HJ5: 51410 | HK5: 51441 | HL5: 51471 | HM5: 51502 | HN5: 51533 | HO5: 51561 | HP5: 51592 | HQ5: 51622 | HR5: 51653 | HS5: 51683 | HT5: 51714 | HU5: 51745 | JM5: 46143 | KH5: Total | Previsão
A7: RECEITAS | JR7: =A7
A8: ITBI | B8: =SUM(C8:AP8) | AB8: 338614.68 | AC8: 371549.5 | AD8: 148554.82 | AE8: 170837.48 | AF8: 191671.94 | AG8: 135342.79 | AH8: 107538.42 | AI8: 89467.66 | AJ8: 89498.31 | AK8: 150726.26 | AL8: 202733.57 | AM8: 93610.35 | AN8: 102176.17 | AO8: 121648.43 | AP8: 76491.71 | AR8: =SUM(AT8:HU8) | JF8: =AP8 | JG8: =SUM(Z8:AK8) | JH8: =SUM(AL8:AP8) | JI8: =SUM(C8:AP8) | JR8: =A8 | JS8: =SUM(C8:AP8) | JU8: =SUM(AT8:AZ8) | JV8: =SUM(BA8:BL8) | JW8: =SUM(BM8:BX8) | JX8: =SUM(BY8:CJ8) | JY8: =SUM(CK8:CV8) | JZ8: =SUM(CW8:HU8) | KG8: =B8 | KH8: =AR8
A9: Receitas Contratadas | B9: =SUM(C9:AP9) | AB9: 2857997.7 | AC9: 3156158.3 | AD9: 1788940.8 | AE9: =3240637.47-AE8+19092.42 | AF9: 1881026.6 | AG9: 2310558.1 | AH9: =2548839.41-78352.42 | AI9: 2551921.9 | AJ9: =2138552.83-41382.42 | AK9: 4079024.8 | AL9: 4698660.8 | AM9: 3087731.2 | AN9: =7279760.12-30654.55 | AO9: =3684860.85-29012.57-24791.61 | AP9: 3243847.9 | AR9: =SUM(AT9:HU9) | AT9: 3574821.4 | AU9: 2767000.7 | AV9: 2446947.7 | AW9: 3652273.5 | AX9: 2932991 | AY9: 2528178 | AZ9: 3753790.3 | BA9: 4012049.6 | BB9: 3544053.9 | BC9: 3455923.5 | BD9: 3435572.3 | BE9: 2126327.4 | BF9: 1595056.3 | BG9: 1682126.5 | BH9: 1531678.3 | BI9: 1005222.9 | BJ9: 965285.41 | BK9: 1636485.1 | BL9: 1675939 | BM9: 913661.51 | BN9: 799107.12 | BO9: 1148317.9 | BP9: 1245834.1 | BQ9: 688488.99 | BR9: 475750.07 | BS9: 483123.56 | BT9: 573091.67 | BU9: 445746.79 | BV9: 445746.73 | BW9: 467823.36 | BX9: 445746.73 | BY9: 443425.39 | BZ9: 367739.24 | CA9: 393894.68 | CB9: 628058.54 | CC9: 835888.25 | CD9: 365111.17 | CE9: 422908.01 | CF9: 492947.79 | CG9: 366947.05 | CH9: 366947.12 | CI9: 380365.1 | CJ9: 358288.47 | CK9: 407361.59 | CL9: 358288.47 | CM9: 372054.76 | CN9: 633307.27 | CO9: 760631.49 | CP9: 354866.26 | CQ9: 418462.35 | CR9: 355407.32 | CS9: 355407.27 | CT9: 355407.27 | CU9: 377483.9 | CV9: 344499.82 | CW9: 393572.94 | CX9: 344499.82 | CY9: 370765.27 | CZ9: 644037.26 | DA9: 652601.6 | DB9: 332584.38 | DC9: 421539.19 | DD9: 333179.68 | DE9: 333179.7 | DF9: 333179.7 | DG9: 355256.33 | DH9: 333179.7 | DI9: 382252.82 | DJ9: 333179.7 | DK9: 359415.99 | DL9: 655336.52 | DM9: 355909.56 | DN9: 333832.92 | DO9: 431713.34 | DP9: 334487.99 | DQ9: 334487.95 | DR9: 334487.95 | DS9: 356564.58 | DT9: 334487.95 | DU9: 383561.07 | DV9: 334487.95 | DW9: 360650.28 | DX9: 531581.81 | DY9: 289043.69 | DZ9: 249797.02 | EA9: 325590.01 | EB9: 201524.86 | EC9: 177058.53 | ED9: 165595.82 | EE9: 187672.45 | EF9: 151718.75 | EG9: 186523.84 | EH9: 114989.8 | EI9: 101752.25 | EJ9: 72859.21 | EK9: 37160.03 | EL9: 0 | EM9: 0 | EN9: 0 | EO9: 0 | EP9: 0 | EQ9: 0 | ER9: 0 | ES9: 0 | ET9: 0 | EU9: 0 | EV9: 0 | EW9: 0 | EX9: 0 | EY9: 0 | EZ9: 0 | FA9: 0 | FB9: 0 | FC9: 0 | FD9: 0 | FE9: 0 | FF9: 0 | FG9: 0 | FH9: 0 | FI9: 0 | FJ9: 0 | FK9: 0 | FL9: 0 | FM9: 0 | FN9: 0 | FO9: 0 | FP9: 0 | FQ9: 0 | FR9: 0 | FS9: 0 | FT9: 0 | FU9: 0 | FV9: 0 | FW9: 0 | FX9: 0 | FY9: 0 | FZ9: 0 | GA9: 0 | GB9: 0 | GC9: 0 | GD9: 0 | GE9: 0 | GF9: 0 | GG9: 0 | GH9: 0 | GI9: 0 | GJ9: 0 | GK9: 0 | GL9: 0 | GM9: 0 | GN9: 0 | GO9: 0 | GP9: 0 | GQ9: 0 | GR9: 0 | GS9: 0 | GT9: 0 | GU9: 0 | GV9: 0 | GW9: 0 | GX9: 0 | GY9: 0 | GZ9: 0 | HA9: 0 | HB9: 0 | HC9: 0 | HD9: 0 | HE9: 0 | HF9: 0 | HG9: 0 | HH9: 0 | HI9: 0 | HJ9: 0 | HK9: 0 | HL9: 0 | HM9: 0 | HN9: 0 | HO9: 0 | HP9: 0 | HQ9: 0 | HR9: 0 | HS9: 0 | HT9: 0 | HU9: 0 | JF9: =AP9 | JG9: =SUM(Z9:AK9) | JH9: =SUM(AL9:AP9) | JI9: =SUM(C9:AP9) | JM9: 2014799.1 | JR9: =A9 | JS9: =SUM(C9:AP9) | JU9: =SUM(AT9:AZ9) | JV9: =SUM(BA9:BL9) | JW9: =SUM(BM9:BX9) | JX9: =SUM(BY9:CJ9) | JY9: =SUM(CK9:CV9) | JZ9: =SUM(CW9:HU9) | KG9: =B9 | KH9: =AR9 | KJ9: =+KG9+KH9+KH12
JF10: =AP10 | JG10: =SUM(Z10:AK10) | JH10: =SUM(AL10:AP10) | JI10: =SUM(C10:AP10) | JR10: =A10 | JS10: =SUM(C10:AP10) | JU10: =SUM(AT10:AZ10) | JV10: =SUM(BA10:BL10) | JW10: =SUM(BM10:BX10) | JX10: =SUM(BY10:CJ10) | JY10: =SUM(CK10:CV10) | JZ10: =SUM(CW10:HU10) | KG10: =B10 | KH10: =AR10
A11: PREVISÃO DE RECEITAS(ESTOQUE) | JF11: =AP11 | JG11: =SUM(Z11:AK11) | JH11: =SUM(AL11:AP11) | JI11: =SUM(C11:AP11) | JR11: =A11 | JS11: =SUM(C11:AP11) | JU11: =SUM(AT11:AZ11) | JV11: =SUM(BA11:BL11) | JW11: =SUM(BM11:BX11) | JX11: =SUM(BY11:CJ11) | JY11: =SUM(CK11:CV11) | JZ11: =SUM(CW11:HU11) | KG11: =B11 | KH11: =AR11
A12: Vendas 05 Lotes a.m. | B12: =SUM(C12:AP12) | C12: 0 | D12: 0 | E12: 0 | F12: 0 | G12: 0 | H12: 0 | I12: 0 | J12: 0 | K12: 0 | L12: 0 | M12: 0 | N12: 0 | O12: 0 | P12: 0 | Q12: 0 | R12: 0 | S12: 0 | T12: 0 | U12: 0 | V12: 0 | AR12: =SUM(AT12:HU12) | AT12: 553013.18 | AU12: 641664.18 | AV12: 730315.18 | AW12: 818966.18 | AX12: 923740.02 | AY12: 1014975.6 | AZ12: 1106211.2 | BA12: 1197446.8 | BB12: 1288682.3 | BC12: 1379917.9 | BD12: 1471153.5 | BE12: 1562389.1 | BF12: 2292757.3 | BG12: 2354685.2 | BH12: 2432736 | BI12: 2497248.4 | BJ12: 2580394.5 | BK12: 2644052.6 | BL12: 2707710.6 | BM12: 2771368.6 | BN12: 2835026.7 | BO12: 2898684.7 | BP12: 2962342.8 | BQ12: 3026000.8 | BR12: 3105781.7 | BS12: 3125526.5 | BT12: 3163905 | BU12: 3182795.4 | BV12: 3201685.8 | BW12: 3219220.6 | BX12: 3236755.4 | BY12: 3254290.2 | BZ12: 3271825 | CA12: 3289359.8 | CB12: 3323017.5 | CC12: 3343136.9 | CD12: 3381889.8 | CE12: 3396270.2 | CF12: 3410650.5 | CG12: 3423675.2 | CH12: 3436699.9 | CI12: 3449582.1 | CJ12: 3462464.4 | CK12: 3475346.7 | CL12: 3505964.1 | CM12: 3521689.4 | CN12: 3556048.4 | CO12: 3570919.2 | CP12: 3585790.1 | CQ12: 3599305.4 | CR12: 3612820.6 | CS12: 3626193.5 | CT12: 3639566.3 | CU12: 3652939.1 | CV12: 3684047.1 | CW12: 3700263 | CX12: 3736975.8 | CY12: 3752251.8 | CZ12: 3767527.8 | DA12: 3781448.1 | DB12: 3795368.5 | DC12: 3809146.5 | DD12: 3822924.4 | DE12: 3836702.4 | DF12: 3868215.4 | DG12: 3884836.4 | DH12: 3921954.4 | DI12: 3937635.5 | DJ12: 3953316.6 | DK12: 3967506.5 | DL12: 3981696.4 | DM12: 3995743.9 | DN12: 4009791.4 | DO12: 4023838.9 | DP12: 4055621.5 | DQ12: 4072512.1 | DR12: 4109899.6 | DS12: 4125850.2 | DT12: 4141800.8 | DU12: 3880882.3 | DV12: 3438130.2 | DW12: 3342071.6 | DX12: 3246012.9 | DY12: 3149954.3 | DZ12: 3053895.6 | EA12: 2957837 | EB12: 2882275.3 | EC12: 2785276.8 | ED12: 2688278.3 | EE12: 2589788.5 | EF12: 2491298.8 | EG12: 2074390.5 | EH12: 1512945.2 | EI12: 1450783.9 | EJ12: 1388622.6 | EK12: 1326461.3 | EL12: 1264300 | EM12: 1194177.7 | EN12: 1124055.4 | EO12: 1052441.9 | EP12: 980828.44 | EQ12: 908826.22 | ER12: 836824 | ES12: 764821.79 | ET12: 715973.55 | EU12: 701856.28 | EV12: 687739.01 | EW12: 673621.74 | EX12: 659504.47 | EY12: 645387.2 | EZ12: 631269.93 | FA12: 616763.92 | FB12: 602257.9 | FC12: 587751.88 | FD12: 573245.86 | FE12: 558739.85 | FF12: 546666.17 | FG12: 538240.99 | FH12: 529815.82 | FI12: 521390.64 | FJ12: 512965.47 | FK12: 504308.19 | FL12: 495650.92 | FM12: 486993.65 | FN12: 478336.38 | FO12: 469679.1 | FP12: 461021.83 | FQ12: 452364.56 | FR12: 443707.28 | FS12: 435050.01 | FT12: 426392.74 | FU12: 417503.37 | FV12: 408614 | FW12: 399724.62 | FX12: 390835.25 | FY12: 381945.88 | FZ12: 373056.51 | GA12: 364167.14 | GB12: 355277.77 | GC12: 346388.4 | GD12: 337499.03 | GE12: 328354.35 | GF12: 319209.67 | GG12: 310064.99 | GH12: 300920.31 | GI12: 291775.63 | GJ12: 282630.95 | GK12: 273486.27 | GL12: 264341.59 | GM12: 255196.91 | GN12: 246052.23 | GO12: 236652.24 | GP12: 227252.25 | GQ12: 217852.26 | GR12: 208452.28 | GS12: 199052.29 | GT12: 189652.3 | GU12: 180252.31 | GV12: 170852.32 | GW12: 161452.34 | GX12: 152052.35 | GY12: 142397.05 | GZ12: 132741.76 | HA12: 123086.46 | HB12: 113431.16 | HC12: 103775.87 | HD12: 94120.571 | HE12: 84465.275 | HF12: 74809.978 | HG12: 65154.682 | HH12: 55499.386 | HI12: 45588.781 | HJ12: 35678.177 | HK12: 25767.572 | HL12: 15856.967 | HM12: 5946.3628 | HN12: 0 | HO12: 0 | HP12: 0 | HQ12: 0 | HR12: 0 | HS12: 0 | HT12: 0 | HU12: 0 | JF12: =AP12 | JG12: =SUM(Z12:AK12) | JH12: =SUM(AL12:AP12) | JI12: =SUM(C12:AP12) | JM12: 553013.18 | JR12: =A12 | JS12: =SUM(C12:AP12) | JU12: =SUM(AT12:AZ12) | JV12: =SUM(BA12:BL12) | JW12: =SUM(BM12:BX12) | JX12: =SUM(BY12:CJ12) | JY12: =SUM(CK12:CV12) | JZ12: =SUM(CW12:HU12) | KG12: =B12 | KH12: =AR12
JF13: =AP13 | JG13: =SUM(Z13:AK13) | JH13: =SUM(AL13:AP13) | JI13: =SUM(C13:AP13) | JR13: =A13 | JS13: =SUM(C13:AP13) | JU13: =SUM(AT13:AZ13) | JV13: =SUM(BA13:BL13) | JW13: =SUM(BM13:BX13) | JX13: =SUM(BY13:CJ13) | JY13: =SUM(CK13:CV13) | JZ13: =SUM(CW13:HU13) | KG13: =B13 | KH13: =AR13
A14: APORTE DE SÓCIOS | JF14: =AP14 | JG14: =SUM(Z14:AK14) | JH14: =SUM(AL14:AP14) | JI14: =SUM(C14:AP14) | JR14: =A14 | JS14: =SUM(C14:AP14) | JU14: =SUM(AT14:AZ14) | JV14: =SUM(BA14:BL14) | JW14: =SUM(BM14:BX14) | JX14: =SUM(BY14:CJ14) | JY14: =SUM(CK14:CV14) | JZ14: =SUM(CW14:HU14) | KG14: =B14 | KH14: =AR14
